Workbook

Sheet Liste
A1: Colonne1 | B1: Prenom | C1: Nom | D1: Colonne32 | E1: Lepool.com | F1: HM | G1: Pool Pro | H1: HN | I1: ESPN | J1: CBS | K1: Moyenne | L1: Écart-type | M1: Moy. Sans HM | N1: Moy - HM
B2: Patrick | C2: Kane | E2: 89 | F2: 90 | G2: 95 | H2: 90 | I2: 91 | J2: 112 | K2: =AVERAGE(Tableau1[[#This Row],[Lepool.com]:[CBS]]) -> 94.5 | L2: =_xlfn.STDEV.S(Tableau1[[#This Row],[Lepool.com]:[CBS]]) -> 8.8260977 | M2: =AVERAGE(E2,G2,H2,I2,Tableau1[[#This Row],[CBS]]) -> 95.4 | N2: =AVERAGE(E2,G2,H2,I2,Tableau1[[#This Row],[CBS]])-Tableau1[[#This Row],[HM]] -> 5.4 | Q2: =VLOOKUP(P2,Tableau1[[Nom]:[Moyenne]],9,0) -> #N/A | R2: =VLOOKUP(P2,Tableau1[[Nom]:[Écart-type]],10,0) -> #N/A | S2: =Q2-R2 -> #N/A | T2: =Q2+R2 -> #N/A
B3: Sidney | C3: Crosby | E3: 87 | F3: 93 | G3: 102 | H3: 95 | I3: 93 | J3: 89 | K3: =AVERAGE(Tableau1[[#This Row],[Lepool.com]:[CBS]]) -> 93.166667 | L3: =_xlfn.STDEV.S(Tableau1[[#This Row],[Lepool.com]:[CBS]]) -> 5.231316 | M3: =AVERAGE(E3,G3,H3,I3,Tableau1[[#This Row],[CBS]]) -> 93.2 | N3: =AVERAGE(E3,G3,H3,I3,Tableau1[[#This Row],[CBS]])-Tableau1[[#This Row],[HM]] -> 0.2 | P3: Hedman | Q3: =VLOOKUP(P3,Tableau1[[Nom]:[Moyenne]],9,0) -> 51.666667 | R3: =VLOOKUP(P3,Tableau1[[Nom]:[Écart-type]],10,0) -> 4.6761808 | S3: =Q3-R3 -> 46.990486 | T3: =Q3+R3 -> 56.342847
B4: Jamie | C4: Benn | E4: 90 | F4: 92 | G4: 91 | H4: 82 | I4: 93 | J4: 92 | K4: =AVERAGE(Tableau1[[#This Row],[Lepool.com]:[CBS]]) -> 90 | L4: =_xlfn.STDEV.S(Tableau1[[#This Row],[Lepool.com]:[CBS]]) -> 4.0496913 | M4: =AVERAGE(E4,G4,H4,I4,Tableau1[[#This Row],[CBS]]) -> 89.6 | N4: =AVERAGE(E4,G4,H4,I4,Tableau1[[#This Row],[CBS]])-Tableau1[[#This Row],[HM]] -> -2.4 | P4: Klingberg | Q4: =VLOOKUP(P4,Tableau1[[Nom]:[Moyenne]],9,0) -> 56.833333 | R4: =VLOOKUP(P4,Tableau1[[Nom]:[Écart-type]],10,0) -> 2.4013885 | S4: =Q4-R4 -> 54.431945 | T4: =Q4+R4 -> 59.234722
B5: Connor | C5: McDavid | E5: 90 | F5: 87 | G5: 85 | H5: 96 | I5: 84 | J5: 82 | K5: =AVERAGE(Tableau1[[#This Row],[Lepool.com]:[CBS]]) -> 87.333333 | L5: =_xlfn.STDEV.S(Tableau1[[#This Row],[Lepool.com]:[CBS]]) -> 5.0464509 | M5: =AVERAGE(E5,G5,H5,I5,Tableau1[[#This Row],[CBS]]) -> 87.4 | N5: =AVERAGE(E5,G5,H5,I5,Tableau1[[#This Row],[CBS]])-Tableau1[[#This Row],[HM]] -> 0.4 | P5: Ekman-Larsson | Q5: =VLOOKUP(P5,Tableau1[[Nom]:[Moyenne]],9,0) -> 57.833333 | R5: =VLOOKUP(P5,Tableau1[[Nom]:[Écart-type]],10,0) -> 1.7224014 | S5: =Q5-R5 -> 56.110932 | T5: =Q5+R5 -> 59.555735
B6: Tyler | C6: Seguin | E6: 85 | F6: 85 | G6: 83 | H6: 75 | I6: 77 | J6: 82 | K6: =AVERAGE(Tableau1[[#This Row],[Lepool.com]:[CBS]]) -> 81.166667 | L6: =_xlfn.STDEV.S(Tableau1[[#This Row],[Lepool.com]:[CBS]]) -> 4.2150524 | M6: =AVERAGE(E6,G6,H6,I6,Tableau1[[#This Row],[CBS]]) -> 80.4 | N6: =AVERAGE(E6,G6,H6,I6,Tableau1[[#This Row],[CBS]])-Tableau1[[#This Row],[HM]] -> -4.6 | P6: Markov | Q6: =VLOOKUP(P6,Tableau1[[Nom]:[Moyenne]],9,0) -> #N/A | R6: =VLOOKUP(P6,Tableau1[[Nom]:[Écart-type]],10,0) -> #N/A | S6: =Q6-R6 -> #N/A | T6: =Q6+R6 -> #N/A
B7: Erik | C7: Karlsson | E7: 78 | F7: 80 | G7: 78 | H7: 77 | I7: 82 | J7: 88 | K7: =AVERAGE(Tableau1[[#This Row],[Lepool.com]:[CBS]]) -> 80.5 | L7: =_xlfn.STDEV.S(Tableau1[[#This Row],[Lepool.com]:[CBS]]) -> 4.0865633 | M7: =AVERAGE(E7,G7,H7,I7,Tableau1[[#This Row],[CBS]]) -> 80.6 | N7: =AVERAGE(E7,G7,H7,I7,Tableau1[[#This Row],[CBS]])-Tableau1[[#This Row],[HM]] -> 0.6 | Q7: =VLOOKUP(P7,Tableau1[[Nom]:[Moyenne]],9,0) -> #N/A | R7: =VLOOKUP(P7,Tableau1[[Nom]:[Écart-type]],10,0) -> #N/A | S7: =Q7-R7 -> #N/A | T7: =Q7+R7 -> #N/A
B8: Johnny | C8: Gaudreau | E8: 80 | F8: 84 | G8: 74 | H8: 80 | I8: 84 | J8: 77 | K8: =AVERAGE(Tableau1[[#This Row],[Lepool.com]:[CBS]]) -> 79.833333 | L8: =_xlfn.STDEV.S(Tableau1[[#This Row],[Lepool.com]:[CBS]]) -> 3.920034 | M8: =AVERAGE(E8,G8,H8,I8,Tableau1[[#This Row],[CBS]]) -> 79 | N8: =AVERAGE(E8,G8,H8,I8,Tableau1[[#This Row],[CBS]])-Tableau1[[#This Row],[HM]] -> -5 | Q8: =VLOOKUP(P8,Tableau1[[Nom]:[Moyenne]],9,0) -> #N/A | R8: =VLOOKUP(P8,Tableau1[[Nom]:[Écart-type]],10,0) -> #N/A | S8: =Q8-R8 -> #N/A | T8: =Q8+R8 -> #N/A
B9: John | C9: Tavares | E9: 80 | F9: 85 | G9: 76 | H9: 83 | I9: 78 | J9: 76 | K9: =AVERAGE(Tableau1[[#This Row],[Lepool.com]:[CBS]]) -> 79.666667 | L9: =_xlfn.STDEV.S(Tableau1[[#This Row],[Lepool.com]:[CBS]]) -> 3.7237973 | M9: =AVERAGE(E9,G9,H9,I9,Tableau1[[#This Row],[CBS]]) -> 78.6 | N9: =AVERAGE(E9,G9,H9,I9,Tableau1[[#This Row],[CBS]])-Tableau1[[#This Row],[HM]] -> -6.4 | Q9: =VLOOKUP(P9,Tableau1[[Nom]:[Moyenne]],9,0) -> #N/A | R9: =VLOOKUP(P9,Tableau1[[Nom]:[Écart-type]],10,0) -> #N/A | S9: =Q9-R9 -> #N/A | T9: =Q9+R9 -> #N/A
B10: Vladimir | C10: Tarasenko | E10: 77 | F10: 77 | G10: 75 | H10: 83 | I10: 81 | J10: 75 | K10: =AVERAGE(Tableau1[[#This Row],[Lepool.com]:[CBS]]) -> 78 | L10: =_xlfn.STDEV.S(Tableau1[[#This Row],[Lepool.com]:[CBS]]) -> 3.2863353 | M10: =AVERAGE(E10,G10,H10,I10,Tableau1[[#This Row],[CBS]]) -> 78.2 | N10: =AVERAGE(E10,G10,H10,I10,Tableau1[[#This Row],[CBS]])-Tableau1[[#This Row],[HM]] -> 1.2
B11: Evgeni | C11: Malkin | E11: 70 | F11: 76 | G11: 82 | H11: 73 | I11: 72 | J11: 90 | K11: =AVERAGE(Tableau1[[#This Row],[Lepool.com]:[CBS]]) -> 77.166667 | L11: =_xlfn.STDEV.S(Tableau1[[#This Row],[Lepool.com]:[CBS]]) -> 7.5476266 | M11: =AVERAGE(E11,G11,H11,I11,Tableau1[[#This Row],[CBS]]) -> 77.4 | N11: =AVERAGE(E11,G11,H11,I11,Tableau1[[#This Row],[CBS]])-Tableau1[[#This Row],[HM]] -> 1.4
B12: Joe | C12: Pavelski | E12: 81 | F12: 79 | G12: 72 | H12: 75 | I12: 76 | J12: 78 | K12: =AVERAGE(Tableau1[[#This Row],[Lepool.com]:[CBS]]) -> 76.833333 | L12: =_xlfn.STDEV.S(Tableau1[[#This Row],[Lepool.com]:[CBS]]) -> 3.1885211 | M12: =AVERAGE(E12,G12,H12,I12,Tableau1[[#This Row],[CBS]]) -> 76.4 | N12: =AVERAGE(E12,G12,H12,I12,Tableau1[[#This Row],[CBS]])-Tableau1[[#This Row],[HM]] -> -2.6
B13: Alexander | C13: Ovechkin | E13: 79 | F13: 79 | G13: 76 | H13: 75 | I13: 73 | J13: 76 | K13: =AVERAGE(Tableau1[[#This Row],[Lepool.com]:[CBS]]) -> 76.333333 | L13: =_xlfn.STDEV.S(Tableau1[[#This Row],[Lepool.com]:[CBS]]) -> 2.3380904 | M13: =AVERAGE(E13,G13,H13,I13,Tableau1[[#This Row],[CBS]]) -> 75.8 | N13: =AVERAGE(E13,G13,H13,I13,Tableau1[[#This Row],[CBS]])-Tableau1[[#This Row],[HM]] -> -3.2
B14: Nicklas | C14: Backstrom | E14: 76 | F14: 77 | G14: 75 | H14: 73 | I14: 76 | J14: 78 | K14: =AVERAGE(Tableau1[[#This Row],[Lepool.com]:[CBS]]) -> 75.833333 | L14: =_xlfn.STDEV.S(Tableau1[[#This Row],[Lepool.com]:[CBS]]) -> 1.7224014 | M14: =AVERAGE(E14,G14,H14,I14,Tableau1[[#This Row],[CBS]]) -> 75.6 | N14: =AVERAGE(E14,G14,H14,I14,Tableau1[[#This Row],[CBS]])-Tableau1[[#This Row],[HM]] -> -1.4
B15: Artemi | C15: Panarin | E15: 71 | F15: 74 | G15: 72 | H15: 66 | I15: 82 | J15: 84 | K15: =AVERAGE(Tableau1[[#This Row],[Lepool.com]:[CBS]]) -> 74.833333 | L15: =_xlfn.STDEV.S(Tableau1[[#This Row],[Lepool.com]:[CBS]]) -> 6.8823446 | M15: =AVERAGE(E15,G15,H15,I15,Tableau1[[#This Row],[CBS]]) -> 75 | N15: =AVERAGE(E15,G15,H15,I15,Tableau1[[#This Row],[CBS]])-Tableau1[[#This Row],[HM]] -> 1
B16: Evgeny | C16: Kuznetsov | E16: 69 | F16: 75 | G16: 72 | H16: 80 | I16: 80 | J16: 71 | K16: =AVERAGE(Tableau1[[#This Row],[Lepool.com]:[CBS]]) -> 74.5 | L16: =_xlfn.STDEV.S(Tableau1[[#This Row],[Lepool.com]:[CBS]]) -> 4.6797436 | M16: =AVERAGE(E16,G16,H16,I16,Tableau1[[#This Row],[CBS]]) -> 74.4 | N16: =AVERAGE(E16,G16,H16,I16,Tableau1[[#This Row],[CBS]])-Tableau1[[#This Row],[HM]] -> -0.6
B17: Nikita | C17: Kucherov | E17: 69 | F17: 72 | G17: 70 | H17: 77 | I17: 74 | J17: 85 | K17: =AVERAGE(Tableau1[[#This Row],[Lepool.com]:[CBS]]) -> 74.5 | L17: =_xlfn.STDEV.S(Tableau1[[#This Row],[Lepool.com]:[CBS]]) -> 5.8906706 | M17: =AVERAGE(E17,G17,H17,I17,Tableau1[[#This Row],[CBS]]) -> 75 | N17: =AVERAGE(E17,G17,H17,I17,Tableau1[[#This Row],[CBS]])-Tableau1[[#This Row],[HM]] -> 3
B18: Claude | C18: Giroux | E18: 75 | F18: 77 | G18: 76 | H18: 73 | I18: 70 | J18: 73 | K18: =AVERAGE(Tableau1[[#This Row],[Lepool.com]:[CBS]]) -> 74 | L18: =_xlfn.STDEV.S(Tableau1[[#This Row],[Lepool.com]:[CBS]]) -> 2.5298221 | M18: =AVERAGE(E18,G18,H18,I18,Tableau1[[#This Row],[CBS]]) -> 73.4 | N18: =AVERAGE(E18,G18,H18,I18,Tableau1[[#This Row],[CBS]])-Tableau1[[#This Row],[HM]] -> -3.6
B19: Steven | C19: Stamkos | E19: 74 | F19: 71 | G19: 77 | H19: 72 | I19: 70 | J19: 78 | K19: =AVERAGE(Tableau1[[#This Row],[Lepool.com]:[CBS]]) -> 73.666667 | L19: =_xlfn.STDEV.S(Tableau1[[#This Row],[Lepool.com]:[CBS]]) -> 3.2659863 | M19: =AVERAGE(E19,G19,H19,I19,Tableau1[[#This Row],[CBS]]) -> 74.2 | N19: =AVERAGE(E19,G19,H19,I19,Tableau1[[#This Row],[CBS]])-Tableau1[[#This Row],[HM]] -> 3.2
B20: Joe | C20: Thornton | E20: 71 | F20: 72 | G20: 70 | H20: 70 | I20: 76 | J20: 77 | K20: =AVERAGE(Tableau1[[#This Row],[Lepool.com]:[CBS]]) -> 72.666667 | L20: =_xlfn.STDEV.S(Tableau1[[#This Row],[Lepool.com]:[CBS]]) -> 3.0767949 | M20: =AVERAGE(E20,G20,H20,I20,Tableau1[[#This Row],[CBS]]) -> 72.8 | N20: =AVERAGE(E20,G20,H20,I20,Tableau1[[#This Row],[CBS]])-Tableau1[[#This Row],[HM]] -> 0.8
B21: Anze | C21: Kopitar | E21: 77 | F21: 72 | G21: 68 | H21: 70 | I21: 73 | J21: 75 | K21: =AVERAGE(Tableau1[[#This Row],[Lepool.com]:[CBS]]) -> 72.5 | L21: =_xlfn.STDEV.S(Tableau1[[#This Row],[Lepool.com]:[CBS]]) -> 3.2710854 | M21: =AVERAGE(E21,G21,H21,I21,Tableau1[[#This Row],[CBS]]) -> 72.6 | N21: =AVERAGE(E21,G21,H21,I21,Tableau1[[#This Row],[CBS]])-Tableau1[[#This Row],[HM]] -> 0.6
... B80: Brandon | C80: Saad | E80: 56 | F80: 57 | G80: 55 | H80: 58 | I80: 54 | J80: 54 | K80: =AVERAGE(Tableau1[[#This Row],[Lepool.com]:[CBS]]) -> 55.666667 | L80: =_xlfn.STDEV.S(Tableau1[[#This Row],[Lepool.com]:[CBS]]) -> 1.6329932 | M80: =AVERAGE(E80,G80,H80,I80,Tableau1[[#This Row],[CBS]]) -> 55.4 | N80: =AVERAGE(E80,G80,H80,I80,Tableau1[[#This Row],[CBS]])-Tableau1[[#This Row],[HM]] -> -1.6
B81: Auston | C81: Matthews | E81: 67 | F81: 52 | H81: 65 | I81: 56 | J81: 37 | K81: =AVERAGE(Tableau1[[#This Row],[Lepool.com]:[CBS]]) -> 55.4 | L81: =_xlfn.STDEV.S(Tableau1[[#This Row],[Lepool.com]:[CBS]]) -> 12.012493 | M81: =AVERAGE(E81,G81,H81,I81,Tableau1[[#This Row],[CBS]]) -> 56.25 | N81: =AVERAGE(E81,G81,H81,I81,Tableau1[[#This Row],[CBS]])-Tableau1[[#This Row],[HM]] -> 4.25
B82: Kyle | C82: Turris | E82: 61 | F82: 66 | G82: 61 | H82: 53 | I82: 46 | J82: 45 | K82: =AVERAGE(Tableau1[[#This Row],[Lepool.com]:[CBS]]) -> 55.333333 | L82: =_xlfn.STDEV.S(Tableau1[[#This Row],[Lepool.com]:[CBS]]) -> 8.6871553 | M82: =AVERAGE(E82,G82,H82,I82,Tableau1[[#This Row],[CBS]]) -> 53.2 | N82: =AVERAGE(E82,G82,H82,I82,Tableau1[[#This Row],[CBS]])-Tableau1[[#This Row],[HM]] -> -12.8
B83: Adam | C83: Henrique | E83: 53 | F83: 55 | G83: 53 | H83: 58 | I83: 57 | J83: 56 | K83: =AVERAGE(Tableau1[[#This Row],[Lepool.com]:[CBS]]) -> 55.333333 | L83: =_xlfn.STDEV.S(Tableau1[[#This Row],[Lepool.com]:[CBS]]) -> 2.0655911 | M83: =AVERAGE(E83,G83,H83,I83,Tableau1[[#This Row],[CBS]]) -> 55.4 | N83: =AVERAGE(E83,G83,H83,I83,Tableau1[[#This Row],[CBS]])-Tableau1[[#This Row],[HM]] -> 0.4
B84: Vincent | C84: Trocheck | E84: 57 | F84: 59 | G84: 58 | H84: 58 | I84: 43 | J84: 55 | K84: =AVERAGE(Tableau1[[#This Row],[Lepool.com]:[CBS]]) -> 55 | L84: =_xlfn.STDEV.S(Tableau1[[#This Row],[Lepool.com]:[CBS]]) -> 6.0332413 | M84: =AVERAGE(E84,G84,H84,I84,Tableau1[[#This Row],[CBS]]) -> 54.2 | N84: =AVERAGE(E84,G84,H84,I84,Tableau1[[#This Row],[CBS]])-Tableau1[[#This Row],[HM]] -> -4.8
B85: T.J. | C85: Oshie | E85: 54 | F85: 57 | G85: 56 | H85: 53 | I85: 53 | J85: 56 | K85: =AVERAGE(Tableau1[[#This Row],[Lepool.com]:[CBS]]) -> 54.833333 | L85: =_xlfn.STDEV.S(Tableau1[[#This Row],[Lepool.com]:[CBS]]) -> 1.7224014 | M85: =AVERAGE(E85,G85,H85,I85,Tableau1[[#This Row],[CBS]]) -> 54.4 | N85: =AVERAGE(E85,G85,H85,I85,Tableau1[[#This Row],[CBS]])-Tableau1[[#This Row],[HM]] -> -2.6
B86: John | C86: Carlson | E86: 52 | F86: 59 | G86: 50 | H86: 57 | I86: 47 | J86: 63 | K86: =AVERAGE(Tableau1[[#This Row],[Lepool.com]:[CBS]]) -> 54.666667 | L86: =_xlfn.STDEV.S(Tableau1[[#This Row],[Lepool.com]:[CBS]]) -> 6.0221812 | M86: =AVERAGE(E86,G86,H86,I86,Tableau1[[#This Row],[CBS]]) -> 53.8 | N86: =AVERAGE(E86,G86,H86,I86,Tableau1[[#This Row],[CBS]])-Tableau1[[#This Row],[HM]] -> -5.2
B87: Jussi | C87: Jokinen | E87: 54 | F87: 52 | G87: 56 | H87: 60 | I87: 50 | J87: 56 | K87: =AVERAGE(Tableau1[[#This Row],[Lepool.com]:[CBS]]) -> 54.666667 | L87: =_xlfn.STDEV.S(Tableau1[[#This Row],[Lepool.com]:[CBS]]) -> 3.5023801 | M87: =AVERAGE(E87,G87,H87,I87,Tableau1[[#This Row],[CBS]]) -> 55.2 | N87: =AVERAGE(E87,G87,H87,I87,Tableau1[[#This Row],[CBS]])-Tableau1[[#This Row],[HM]] -> 3.2
B88: Jaromir | C88: Jagr | E88: 54 | F88: 57 | G88: 52 | H88: 50 | I88: 54 | J88: 60 | K88: =AVERAGE(Tableau1[[#This Row],[Lepool.com]:[CBS]]) -> 54.5 | L88: =_xlfn.STDEV.S(Tableau1[[#This Row],[Lepool.com]:[CBS]]) -> 3.5637059 | M88: =AVERAGE(E88,G88,H88,I88,Tableau1[[#This Row],[CBS]]) -> 54 | N88: =AVERAGE(E88,G88,H88,I88,Tableau1[[#This Row],[CBS]])-Tableau1[[#This Row],[HM]] -> -3
B89: Jeff | C89: Skinner | E89: 56 | F89: 55 | G89: 56 | H89: 55 | I89: 53 | J89: 52 | K89: =AVERAGE(Tableau1[[#This Row],[Lepool.com]:[CBS]]) -> 54.5 | L89: =_xlfn.STDEV.S(Tableau1[[#This Row],[Lepool.com]:[CBS]]) -> 1.6431677 | M89: =AVERAGE(E89,G89,H89,I89,Tableau1[[#This Row],[CBS]]) -> 54.4 | N89: =AVERAGE(E89,G89,H89,I89,Tableau1[[#This Row],[CBS]])-Tableau1[[#This Row],[HM]] -> -0.6
B90: Ondrej | C90: Palat | E90: 52 | F90: 55 | G90: 57 | H90: 55 | I90: 52 | J90: 56 | K90: =AVERAGE(Tableau1[[#This Row],[Lepool.com]:[CBS]]) -> 54.5 | L90: =_xlfn.STDEV.S(Tableau1[[#This Row],[Lepool.com]:[CBS]]) -> 2.0736441 | M90: =AVERAGE(E90,G90,H90,I90,Tableau1[[#This Row],[CBS]]) -> 54.4 | N90: =AVERAGE(E90,G90,H90,I90,Tableau1[[#This Row],[CBS]])-Tableau1[[#This Row],[HM]] -> -0.6
B91: Patrick | C91: Sharp | E91: 56 | F91: 54 | G91: 48 | H91: 56 | I91: 55 | J91: 57 | K91: =AVERAGE(Tableau1[[#This Row],[Lepool.com]:[CBS]]) -> 54.333333 | L91: =_xlfn.STDEV.S(Tableau1[[#This Row],[Lepool.com]:[CBS]]) -> 3.2659863 | M91: =AVERAGE(E91,G91,H91,I91,Tableau1[[#This Row],[CBS]]) -> 54.4 | N91: =AVERAGE(E91,G91,H91,I91,Tableau1[[#This Row],[CBS]])-Tableau1[[#This Row],[HM]] -> 0.4
B92: Andrew | C92: Ladd | E92: 56 | F92: 50 | G92: 54 | H92: 66 | I92: 51 | J92: 49 | K92: =AVERAGE(Tableau1[[#This Row],[Lepool.com]:[CBS]]) -> 54.333333 | L92: =_xlfn.STDEV.S(Tableau1[[#This Row],[Lepool.com]:[CBS]]) -> 6.2822501 | M92: =AVERAGE(E92,G92,H92,I92,Tableau1[[#This Row],[CBS]]) -> 55.2 | N92: =AVERAGE(E92,G92,H92,I92,Tableau1[[#This Row],[CBS]])-Tableau1[[#This Row],[HM]] -> 5.2
B93: Dustin | C93: Byfuglien | E93: 57 | F93: 51 | G93: 55 | H93: 53 | I93: 51 | J93: 56 | K93: =AVERAGE(Tableau1[[#This Row],[Lepool.com]:[CBS]]) -> 53.833333 | L93: =_xlfn.STDEV.S(Tableau1[[#This Row],[Lepool.com]:[CBS]]) -> 2.5625508 | M93: =AVERAGE(E93,G93,H93,I93,Tableau1[[#This Row],[CBS]]) -> 54.4 | N93: =AVERAGE(E93,G93,H93,I93,Tableau1[[#This Row],[CBS]])-Tableau1[[#This Row],[HM]] -> 3.4
... B116: Robby | C116: Fabbri | E116: 48 | F116: 48 | G116: 51 | H116: 54 | I116: 49 | J116: 50 | K116: =AVERAGE(Tableau1[[#This Row],[Lepool.com]:[CBS]]) -> 50 | L116: =_xlfn.STDEV.S(Tableau1[[#This Row],[Lepool.com]:[CBS]]) -> 2.2803509 | M116: =AVERAGE(E116,G116,H116,I116,Tableau1[[#This Row],[CBS]]) -> 50.4 | N116: =AVERAGE(E116,G116,H116,I116,Tableau1[[#This Row],[CBS]])-Tableau1[[#This Row],[HM]] -> 2.4
B117: Jiri | C117: Hudler | E117: 51 | G117: 44 | H117: 53 | I117: 48 | J117: 54 | K117: =AVERAGE(Tableau1[[#This Row],[Lepool.com]:[CBS]]) -> 50 | L117: =_xlfn.STDEV.S(Tableau1[[#This Row],[Lepool.com]:[CBS]]) -> 4.0620192 | M117: =AVERAGE(E117,G117,H117,I117,Tableau1[[#This Row],[CBS]]) -> 50 | N117: =AVERAGE(E117,G117,H117,I117,Tableau1[[#This Row],[CBS]])-Tableau1[[#This Row],[HM]] -> 50
B118: Tomas | C118: Hertl | E118: 51 | F118: 52 | G118: 50 | H118: 49 | I118: 51 | J118: 46 | K118: =AVERAGE(Tableau1[[#This Row],[Lepool.com]:[CBS]]) -> 49.833333 | L118: =_xlfn.STDEV.S(Tableau1[[#This Row],[Lepool.com]:[CBS]]) -> 2.1369761 | M118: =AVERAGE(E118,G118,H118,I118,Tableau1[[#This Row],[CBS]]) -> 49.4 | N118: =AVERAGE(E118,G118,H118,I118,Tableau1[[#This Row],[CBS]])-Tableau1[[#This Row],[HM]] -> -2.6
B119: Jakob | C119: Sifverberg | F119: 44 | H119: 55 | K119: =AVERAGE(Tableau1[[#This Row],[Lepool.com]:[CBS]]) -> 49.5 | L119: =_xlfn.STDEV.S(Tableau1[[#This Row],[Lepool.com]:[CBS]]) -> 7.7781746 | M119: =AVERAGE(E119,G119,H119,I119,Tableau1[[#This Row],[CBS]]) -> 55 | N119: =AVERAGE(E119,G119,H119,I119,Tableau1[[#This Row],[CBS]])-Tableau1[[#This Row],[HM]] -> 11
B120: Shayne | C120: Gostisbehere | E120: 51 | F120: 51 | G120: 44 | H120: 43 | J120: 58 | K120: =AVERAGE(Tableau1[[#This Row],[Lepool.com]:[CBS]]) -> 49.4 | L120: =_xlfn.STDEV.S(Tableau1[[#This Row],[Lepool.com]:[CBS]]) -> 6.1073726 | M120: =AVERAGE(E120,G120,H120,I120,Tableau1[[#This Row],[CBS]]) -> 49 | N120: =AVERAGE(E120,G120,H120,I120,Tableau1[[#This Row],[CBS]])-Tableau1[[#This Row],[HM]] -> -2
...

Sheet Manquants
A1: Evander Kane
A2: David Pastrnak
A3: Jimmy Vesey | C3: Iginla | D3: =VLOOKUP(Manquants!C3,Tableau1[[Nom]:[HM]],4,0) -> 39 | I3: Colonne1 | J3: Colonne2 | K3: PoolPro | L3: HN | M3: Colonne3
C4: Hossa | D4: =VLOOKUP(Manquants!C4,Tableau1[[Nom]:[HM]],4,0) -> 40 | F4: Hossa | G4: #N/A | I4: David | J4: Backes | K4: 52 | L4: 50 | M4: 46 | O4: 52 | P4: 50
C5: Purcell | D5: =VLOOKUP(Manquants!C5,Tableau1[[Nom]:[HM]],4,0) -> 40 | F5: Rieder | G5: #N/A | I5: Tyler | J5: Bozak | K5: 44 | M5: 45 | O5: 44
C6: Puljujarvi | D6: =VLOOKUP(Manquants!C6,Tableau1[[Nom]:[HM]],4,0) -> 40 | F6: Brouwer | G6: #N/A | I6: Troy | J6: Brouwer | K6: 49 | L6: 43 | M6: 40 | O6: 49 | P6: 43
C7: Rieder | D7: =VLOOKUP(Manquants!C7,Tableau1[[Nom]:[HM]],4,0) -> 40 | F7: Lehtera | G7: #N/A | I7: Andre | J7: Burakovsky | K7: 36 | L7: 51 | M7: 43 | O7: 36 | P7: 51
C8: Brouwer | D8: =VLOOKUP(Manquants!C8,Tableau1[[Nom]:[HM]],4,0) -> 40 | F8: Nylander | I8: Shane | J8: Doan | K8: 42 | L8: 42 | M8: 43 | O8: 42 | P8: 42
C9: Hartnell | D9: =VLOOKUP(Manquants!C9,Tableau1[[Nom]:[HM]],4,0) -> 40 | F9: Stafford | G9: #N/A | I9: Joonas | J9: Donskoi | K9: 42 | M9: 43 | O9: 42
C10: Smith | D10: =VLOOKUP(Manquants!C10,Tableau1[[Nom]:[HM]],4,0) -> 52 | F10: Muzzin | I10: Tyler | J10: Ennis | K10: 37 | L10: 42 | M10: 44 | O10: 37 | P10: 42
C11: Lehtera | D11: =VLOOKUP(Manquants!C11,Tableau1[[Nom]:[HM]],4,0) -> 41 | F11: Seabrook | I11: Carl | J11: Hagelin | K11: 41 | L11: 45 | M11: 42 | O11: 41 | P11: 45
C12: Miller | D12: =VLOOKUP(Manquants!C12,Tableau1[[Nom]:[HM]],4,0) -> 41 | F12: Killorn | I12: Dougie | J12: Hamilton | K12: 47 | L12: 44 | M12: 45 | O12: 47 | P12: 44
C13: Nylander | D13: =VLOOKUP(Manquants!C13,Tableau1[[Nom]:[HM]],4,0) -> 41 | F13: Hagelin | I13: Marian | J13: Hossa | K13: 42 | L13: 43 | M13: 40 | O13: 42 | P13: 43
C14: Vanek | D14: =VLOOKUP(Manquants!C14,Tableau1[[Nom]:[HM]],4,0) -> 41 | F14: Donskoi | I14: Alex | J14: Killorn | K14: 43 | L14: 40 | M14: 42 | O14: 43 | P14: 40
C15: Stafford | D15: =VLOOKUP(Manquants!C15,Tableau1[[Nom]:[HM]],4,0) -> 41 | F15: Vermette | G15: #N/A | I15: Nick | J15: Leddy | K15: 42 | L15: 41 | M15: 45 | O15: 42 | P15: 41
C16: Muzzin | D16: =VLOOKUP(Manquants!C16,Tableau1[[Nom]:[HM]],4,0) -> 42 | F16: Burakovsky | G16: #N/A | I16: Jori | J16: Lehtera | K16: 40 | L16: 36 | M16: 41 | O16: 40 | P16: 36
C17: Seabrook | D17: =VLOOKUP(Manquants!C17,Tableau1[[Nom]:[HM]],4,0) -> 42 | F17: Doan | G17: #N/A | I17: Elias | J17: Lindholm | K17: 44 | L17: 31 | M17: 47 | O17: 44 | P17: 31
C18: Ribeiro | D18: =VLOOKUP(Manquants!C18,Tableau1[[Nom]:[HM]],4,0) -> 42 | F18: Ennis | I18: Jake | J18: Muzzin | K18: 42 | L18: 39 | M18: 42 | O18: 42 | P18: 39
C19: Killorn | D19: =VLOOKUP(Manquants!C19,Tableau1[[Nom]:[HM]],4,0) -> 42 | F19: Sifverberg | G19: #N/A | I19: William | J19: Nylander | L19: 55 | M19: 41 | P19: 55
C20: Ekblad | D20: =VLOOKUP(Manquants!C20,Tableau1[[Nom]:[HM]],4,0) -> 42 | F20: Yandle | I20: Jean-Gabriel | J20: Pageau | M20: 47
C21: Hagelin | D21: =VLOOKUP(Manquants!C21,Tableau1[[Nom]:[HM]],4,0) -> 42 | F21: Leddy | G21: #N/A | I21: Tanner | J21: Pearson | K21: 43 | L21: 45 | M21: 45 | O21: 43 | P21: 45
C22: Colborne | D22: =VLOOKUP(Manquants!C22,Tableau1[[Nom]:[HM]],4,0) -> 42 | F22: Hamilton | I22: Mathieu | J22: Perreault | K22: 45 | L22: 42 | M22: 46 | O22: 45 | P22: 42
C23: Duclair | D23: =VLOOKUP(Manquants!C23,Tableau1[[Nom]:[HM]],4,0) -> 42 | F23: Pearson | I23: Tobias | J23: Rieder | K23: 41 | L23: 43 | M23: 40 | O23: 41 | P23: 43
C24: Donskoi | D24: =VLOOKUP(Manquants!C24,Tableau1[[Nom]:[HM]],4,0) -> 43 | F24: Bozak | G24: #N/A | I24: Morgan | J24: Rielly | K24: 42 | L24: 48 | M24: 46 | O24: 42 | P24: 48
C25: Backlund | D25: =VLOOKUP(Manquants!C25,Tableau1[[Nom]:[HM]],4,0) -> 43 | F25: Rielly | I25: Brent | J25: Seabrook | K25: 42 | L25: 39 | M25: 42 | O25: 42 | P25: 39
C26: Vermette | D26: =VLOOKUP(Manquants!C26,Tableau1[[Nom]:[HM]],4,0) -> 43 | F26: Perreault | G26: #N/A | I26: Jakob | J26: Sifverberg | K26: 42 | L26: 51 | M26: 44 | O26: 42 | P26: 51
C27: Burakovsky | D27: =VLOOKUP(Manquants!C27,Tableau1[[Nom]:[HM]],4,0) -> 43 | F27: Backes | G27: #N/A | I27: Drew | J27: Stafford | K27: 36 | L27: 36 | M27: 41 | O27: 36 | P27: 36
C28: Doan | D28: =VLOOKUP(Manquants!C28,Tableau1[[Nom]:[HM]],4,0) -> 43 | F28: Lindholm | G28: #N/A | I28: Antoine | J28: Vermette | L28: 35 | M28: 43 | P28: 35
C29: Zajac | D29: =VLOOKUP(Manquants!C29,Tableau1[[Nom]:[HM]],4,0) -> 44 | F29: Pageau | I29: Keith | J29: Yandle | K29: 49 | M29: 45 | O29: 49
C30: Horvat | D30: =VLOOKUP(Manquants!C30,Tableau1[[Nom]:[HM]],4,0) -> 44
C31: Foligno | D31: =VLOOKUP(Manquants!C31,Tableau1[[Nom]:[HM]],4,0) -> 44 | I31: Seth | J31: Jones
C32: Ennis | D32: =VLOOKUP(Manquants!C32,Tableau1[[Nom]:[HM]],4,0) -> 44 | G32: #N/A | I32: David | J32: Pastrnak
C33: Anisimov | D33: =VLOOKUP(Manquants!C33,Tableau1[[Nom]:[HM]],4,0) -> 44 | I33: TJ | J33: Brodie
C34: Sifverberg | D34: =VLOOKUP(Manquants!C34,Tableau1[[Nom]:[HM]],4,0) -> 44 | G34: #N/A | I34: Mitch | J34: Marner
C35: Nelson | D35: =VLOOKUP(Manquants!C35,Tableau1[[Nom]:[HM]],4,0) -> 44
C36: Yandle | D36: =VLOOKUP(Manquants!C36,Tableau1[[Nom]:[HM]],4,0) -> 45 | G36: #N/A
C37: Leddy | D37: =VLOOKUP(Manquants!C37,Tableau1[[Nom]:[HM]],4,0) -> 45 | G37: #N/A
C38: Hamilton | D38: =VLOOKUP(Manquants!C38,Tableau1[[Nom]:[HM]],4,0) -> 45 | E38: 19 | G38: #N/A
C39: Shattenkirk | D39: =VLOOKUP(Manquants!C39,Tableau1[[Nom]:[HM]],4,0) -> 45
C40: Faulk | D40: =VLOOKUP(Manquants!C40,Tableau1[[Nom]:[HM]],4,0) -> 45
...

Sheet ESPN
A2: 1 | B2: Jamie Benn*, Dal LW O | C2: 41 | D2: 52 | E2: =C2+D2 -> 93 | H2: Jamie Benn | I2: 93 | K2: Sidney | L2: Crosby | M2: =K2&" "&L2 -> Sidney Crosby | N2: =VLOOKUP(M2,$H$2:$I$201,2,0) -> 93 | P2: Marian | Q2: Hossa | W2: 44
A3: 2 | B3: Patrick Kane, Chi RW | C3: 43 | D3: 48 | E3: =C3+D3 -> 91 | H3: Patrick Kane | I3: 91 | K3: Patrick | L3: Kane | M3: =K3&" "&L3 -> Patrick Kane | N3: =VLOOKUP(M3,$H$2:$I$201,2,0) -> 91 | P3: Tobias | Q3: Rieder
A4: 3 | B4: Sidney Crosby, Pit C | C4: 35 | D4: 58 | E4: =C4+D4 -> 93 | H4: Sidney Crosby | I4: 93 | K4: Connor | L4: McDavid | M4: =K4&" "&L4 -> Connor McDavid | N4: =VLOOKUP(M4,$H$2:$I$201,2,0) -> 84 | P4: Troy | Q4: Brouwer
A5: 4 | B5: Joe Pavelski, SJ C | C5: 38 | D5: 38 | E5: =C5+D5 -> 76 | H5: Joe Pavelski | I5: 76 | K5: Jamie | L5: Benn | M5: =K5&" "&L5 -> Jamie Benn | N5: =VLOOKUP(M5,$H$2:$I$201,2,0) -> 93 | P5: Jori | Q5: Lehtera | W5: 40
A6: 5 | B6: Erik Karlsson, Ott D | C6: 19 | D6: 63 | E6: =C6+D6 -> 82 | H6: Erik Karlsson | I6: 82 | K6: Tyler | L6: Seguin | M6: =K6&" "&L6 -> Tyler Seguin | N6: =VLOOKUP(M6,$H$2:$I$201,2,0) -> 77 | P6: William | Q6: Nylander | W6: 47
A7: 6 | B7: Vladimir Tarasenko, StL RW | C7: 42 | D7: 39 | E7: =C7+D7 -> 81 | H7: Vladimir Tarasenko | I7: 81 | K7: John | L7: Tavares | M7: =K7&" "&L7 -> John Tavares | N7: =VLOOKUP(M7,$H$2:$I$201,2,0) -> 78 | P7: Drew | Q7: Stafford
A8: 7 | B8: Alex Ovechkin, Wsh RW | C8: 51 | D8: 22 | E8: =C8+D8 -> 73 | H8: Alex Ovechkin | I8: 73 | K8: Johnny | L8: Gaudreau | M8: =K8&" "&L8 -> Johnny Gaudreau | N8: =VLOOKUP(M8,$H$2:$I$201,2,0) -> 84 | P8: Jake | Q8: Muzzin | W8: 39
A9: 8 | B9: Connor McDavid, Edm C | C9: 30 | D9: 54 | E9: =C9+D9 -> 84 | H9: Connor McDavid | I9: 84 | K9: Erik | L9: Karlsson | M9: =K9&" "&L9 -> Erik Karlsson | N9: =VLOOKUP(M9,$H$2:$I$201,2,0) -> 82 | P9: Brent | Q9: Seabrook | W9: 37
A10: 9 | B10: Brent Burns, SJ D | C10: 28 | D10: 43 | E10: =C10+D10 -> 71 | H10: Brent Burns | I10: 71 | K10: Vladimir | L10: Tarasenko | M10: =K10&" "&L10 -> Vladimir Tarasenko | N10: =VLOOKUP(M10,$H$2:$I$201,2,0) -> 81 | P10: Alex | Q10: Killorn | W10: 39
A11: 10 | B11: Johnny Gaudreau, Cgy LW | C11: 34 | D11: 50 | E11: =C11+D11 -> 84 | H11: Johnny Gaudreau | I11: 84 | K11: Alexander | L11: Ovechkin | M11: =K11&" "&L11 -> Alexander Ovechkin | N11: 73 | P11: Carl | Q11: Hagelin | W11: 46
A12: 11 | B12: John Tavares, NYI C | C12: 36 | D12: 42 | E12: =C12+D12 -> 78 | H12: John Tavares | I12: 78 | K12: Joe | L12: Pavelski | M12: =K12&" "&L12 -> Joe Pavelski | N12: =VLOOKUP(M12,$H$2:$I$201,2,0) -> 76 | P12: Joonas | Q12: Donskoi
A13: 12 | B13: Artemi Panarin, Chi C | C13: 32 | D13: 50 | E13: =C13+D13 -> 82 | H13: Artemi Panarin | I13: 82 | K13: Nicklas | L13: Backstrom | M13: =K13&" "&L13 -> Nicklas Backstrom | N13: =VLOOKUP(M13,$H$2:$I$201,2,0) -> 76 | P13: Antoine | Q13: Vermette
A14: 13 | B14: Tyler Seguin*, Dal C O | C14: 35 | D14: 42 | E14: =C14+D14 -> 77 | H14: Tyler Seguin | I14: 77 | K14: Claude | L14: Giroux | M14: =K14&" "&L14 -> Claude Giroux | N14: =VLOOKUP(M14,$H$2:$I$201,2,0) -> 70 | P14: Andre | Q14: Burakovsky
A15: 14 | B15: Nikita Kucherov, TB RW | C15: 34 | D15: 40 | E15: =C15+D15 -> 74 | H15: Nikita Kucherov | I15: 74 | K15: Evgeni | L15: Malkin | M15: =K15&" "&L15 -> Evgeni Malkin | N15: =VLOOKUP(M15,$H$2:$I$201,2,0) -> 72 | P15: Shane | Q15: Doan | W15: 41
A16: 15 | B16: Nicklas Backstrom, Wsh C | C16: 19 | D16: 57 | E16: =C16+D16 -> 76 | H16: Nicklas Backstrom | I16: 76 | K16: Evgeny | L16: Kuznetsov | M16: =K16&" "&L16 -> Evgeny Kuznetsov | N16: =VLOOKUP(M16,$H$2:$I$201,2,0) -> 80 | P16: Tyler | Q16: Ennis
A17: 16 | B17: Patrice Bergeron, Bos C | C17: 26 | D17: 34 | E17: =C17+D17 -> 60 | H17: Patrice Bergeron | I17: 60 | K17: Steven | L17: Stamkos | M17: =K17&" "&L17 -> Steven Stamkos | N17: =VLOOKUP(M17,$H$2:$I$201,2,0) -> 70 | P17: Jakob | Q17: Sifverberg
A18: 17 | B18: Evgeni Malkin, Pit C | C18: 27 | D18: 45 | E18: =C18+D18 -> 72 | H18: Evgeni Malkin | I18: 72 | K18: Nikita | L18: Kucherov | M18: =K18&" "&L18 -> Nikita Kucherov | N18: =VLOOKUP(M18,$H$2:$I$201,2,0) -> 74 | P18: Keith | Q18: Yandle | W18: 46
A19: 18 | B19: Dustin Byfuglien, Wpg D | C19: 18 | D19: 33 | E19: =C19+D19 -> 51 | H19: Dustin Byfuglien | I19: 51 | K19: Anze | L19: Kopitar | M19: =K19&" "&L19 -> Anze Kopitar | N19: =VLOOKUP(M19,$H$2:$I$201,2,0) -> 73 | P19: Nick | Q19: Leddy | W19: 35
A20: 19 | B20: Blake Wheeler, Wpg RW | C20: 30 | D20: 43 | E20: =C20+D20 -> 73 | H20: Blake Wheeler | I20: 73 | K20: Ryan | L20: Getzlaf | M20: =K20&" "&L20 -> Ryan Getzlaf | N20: =VLOOKUP(M20,$H$2:$I$201,2,0) -> 66 | P20: Dougie | Q20: Hamilton | W20: 44
A21: 20 | B21: Steven Stamkos, TB C | C21: 40 | D21: 30 | E21: =C21+D21 -> 70 | H21: Steven Stamkos | I21: 70 | K21: Artemi | L21: Panarin | M21: =K21&" "&L21 -> Artemi Panarin | N21: =VLOOKUP(M21,$H$2:$I$201,2,0) -> 82 | P21: Tanner | Q21: Pearson
A22: 21 | B22: Anze Kopitar, LA C | C22: 23 | D22: 50 | E22: =C22+D22 -> 73 | H22: Anze Kopitar | I22: 73 | K22: Joe | L22: Thornton | M22: =K22&" "&L22 -> Joe Thornton | N22: =VLOOKUP(M22,$H$2:$I$201,2,0) -> 76 | P22: Tyler | Q22: Bozak
A23: 22 | B23: Joe Thornton, SJ C | C23: 17 | D23: 59 | E23: =C23+D23 -> 76 | H23: Joe Thornton | I23: 76 | K23: Blake | L23: Wheeler | M23: =K23&" "&L23 -> Blake Wheeler | N23: =VLOOKUP(M23,$H$2:$I$201,2,0) -> 73 | P23: Morgan | Q23: Rielly
A24: 23 | B24: Evgeny Kuznetsov, Wsh C | C24: 25 | D24: 55 | E24: =C24+D24 -> 80 | H24: Evgeny Kuznetsov | I24: 80 | K24: Aleksander | L24: Barkov | M24: =K24&" "&L24 -> Aleksander Barkov | N24: =VLOOKUP(M24,$H$2:$I$201,2,0) -> 59 | P24: Mathieu | Q24: Perreault
A25: 24 | B25: Corey Perry, Ana RW | C25: 33 | D25: 30 | E25: =C25+D25 -> 63 | H25: Corey Perry | I25: 63 | K25: Mark | L25: Scheifele | M25: =K25&" "&L25 -> Mark Scheifele | N25: =VLOOKUP(M25,$H$2:$I$201,2,0) -> 61 | P25: David | Q25: Backes | W25: 52
A26: 25 | B26: Phil Kessel*, Pit RW O | C26: 28 | D26: 38 | E26: =C26+D26 -> 66 | H26: Phil Kessel | I26: 66 | K26: Ryan | L26: Johansen | M26: =K26&" "&L26 -> Ryan Johansen | N26: =VLOOKUP(M26,$H$2:$I$201,2,0) -> 54 | P26: Elias | Q26: Lindholm
A27: 26 | B27: Wayne Simmonds, Phi LW | C27: 30 | D27: 27 | E27: =C27+D27 -> 57 | H27: Wayne Simmonds | I27: 57 | K27: Filip | L27: Forsberg | M27: =K27&" "&L27 -> Filip Forsberg | N27: =VLOOKUP(M27,$H$2:$I$201,2,0) -> 57 | P27: Jean-Gabriel | Q27: Pageau
A28: 27 | B28: Oliver Ekman-Larsson, Ari D | C28: 24 | D28: 32 | E28: =C28+D28 -> 56 | H28: Oliver Ekman-Larsson | I28: 56 | K28: Sean | L28: Monahan | M28: =K28&" "&L28 -> Sean Monahan | N28: =VLOOKUP(M28,$H$2:$I$201,2,0) -> 68
A29: 28 | B29: P.K. Subban*, Nsh D O | C29: 9 | D29: 44 | E29: =C29+D29 -> 53 | H29: P.K. Subban | I29: 53 | K29: Corey | L29: Perry | M29: =K29&" "&L29 -> Corey Perry | N29: =VLOOKUP(M29,$H$2:$I$201,2,0) -> 63
A30: 29 | B30: Claude Giroux, Phi C | C30: 24 | D30: 46 | E30: =C30+D30 -> 70 | H30: Claude Giroux | I30: 70 | K30: Taylor | L30: Hall | M30: =K30&" "&L30 -> Taylor Hall | N30: =VLOOKUP(M30,$H$2:$I$201,2,0) -> 63
A31: 30 | B31: Tyler Toffoli, LA RW | C31: 34 | D31: 30 | E31: =C31+D31 -> 64 | H31: Tyler Toffoli | I31: 64 | K31: Max | L31: Pacioretty | M31: =K31&" "&L31 -> Max Pacioretty | N31: =VLOOKUP(M31,$H$2:$I$201,2,0) -> 61
A32: 31 | B32: Ryan Getzlaf, Ana C | C32: 15 | D32: 51 | E32: =C32+D32 -> 66 | H32: Ryan Getzlaf | I32: 66 | K32: Jakub | L32: Voracek | M32: =K32&" "&L32 -> Jakub Voracek | N32: =VLOOKUP(M32,$H$2:$I$201,2,0) -> 57
A33: 32 | B33: Drew Doughty, LA D | C33: 11 | D33: 35 | E33: =C33+D33 -> 46 | H33: Drew Doughty | I33: 46 | K33: Jonathan | L33: Huberdeau | M33: =K33&" "&L33 -> Jonathan Huberdeau | N33: =VLOOKUP(M33,$H$2:$I$201,2,0) -> 60
A34: 33 | B34: Kris Letang, Pit D | C34: 14 | D34: 39 | E34: =C34+D34 -> 53 | H34: Kris Letang | I34: 53 | K34: Brent | L34: Burns | M34: =K34&" "&L34 -> Brent Burns | N34: =VLOOKUP(M34,$H$2:$I$201,2,0) -> 71
A35: 34 | B35: Roman Josi, Nsh D | C35: 14 | D35: 49 | E35: =C35+D35 -> 63 | H35: Roman Josi | I35: 63 | K35: Jack | L35: Eichel | M35: =K35&" "&L35 -> Jack Eichel | N35: =VLOOKUP(M35,$H$2:$I$201,2,0) -> 64
A36: 35 | B36: Max Pacioretty, Mon LW | C36: 32 | D36: 29 | E36: =C36+D36 -> 61 | H36: Max Pacioretty | I36: 61 | K36: Logan | L36: Couture | M36: =K36&" "&L36 -> Logan Couture | N36: =VLOOKUP(M36,$H$2:$I$201,2,0) -> 56
A37: 36 | B37: Mark Giordano, Cgy D | C37: 17 | D37: 35 | E37: =C37+D37 -> 52 | H37: Mark Giordano | I37: 52 | K37: David | L37: Krejci | M37: =K37&" "&L37 -> David Krejci | N37: =VLOOKUP(M37,$H$2:$I$201,2,0) -> 55
A38: 37 | B38: Daniel Sedin, Van LW | C38: 25 | D38: 41 | E38: =C38+D38 -> 66 | H38: Daniel Sedin | I38: 66 | K38: Jordan | L38: Eberle | M38: =K38&" "&L38 -> Jordan Eberle | N38: =VLOOKUP(M38,$H$2:$I$201,2,0) -> 56
A39: 38 | B39: Jonathan Toews, Chi C | C39: 28 | D39: 32 | E39: =C39+D39 -> 60 | H39: Jonathan Toews | I39: 60 | K39: Kristopher | L39: Letang | M39: =K39&" "&L39 -> Kristopher Letang | N39: 53
A40: 39 | B40: Shea Weber, Mon D | C40: 17 | D40: 28 | E40: =C40+D40 -> 45 | H40: Shea Weber | I40: 45 | K40: Phil | L40: Kessel | M40: =K40&" "&L40 -> Phil Kessel | N40: =VLOOKUP(M40,$H$2:$I$201,2,0) -> 66
A41: 40 | B41: Brad Marchand, Bos LW | C41: 29 | D41: 23 | E41: =C41+D41 -> 52 | H41: Brad Marchand | I41: 52 | K41: Jonathan | L41: Toews | M41: =K41&" "&L41 -> Jonathan Toews | N41: =VLOOKUP(M41,$H$2:$I$201,2,0) -> 60
...

Sheet CBS
A1: Evgeni Malkin, PIT | B1: 78 | C1: 40 | D1: 49 | E1: 90 | F1: 39 | G1: 20 | H1: 0 | I1: 107 | J1: 384 | M1: Evgeni | N1: Malkin | O1: =M1&" "&N1 -> Evgeni Malkin | P1: 90 | R1: Teuvo | S1: Teravainen | T1: =R1&" "&S1 -> Teuvo Teravainen | U1: =VLOOKUP(T1,$O$1:$P$511,2,0) -> 29 | V1: 29
A2: Sidney Crosby, PIT | B2: 78 | C2: 36 | D2: 53 | E2: 89 | F2: 38 | G2: 16 | H2: 0 | I2: 45 | J2: 356 | M2: Sidney | N2: Crosby | O2: =M2&" "&N2 -> Sidney Crosby | P2: 89 | R2: Alexander | S2: Wennberg | T2: =R2&" "&S2 -> Alexander Wennberg | U2: =VLOOKUP(T2,$O$1:$P$511,2,0) -> 49 | V2: 49
A3: Tyler Seguin, DAL | B3: 78 | C3: 37 | D3: 44 | E3: 82 | F3: 29 | G3: 15 | H3: 0 | I3: 21 | J3: 337 | M3: Tyler | N3: Seguin | O3: =M3&" "&N3 -> Tyler Seguin | P3: 82 | R3: Bo | S3: Horvat | T3: =R3&" "&S3 -> Bo Horvat | U3: =VLOOKUP(T3,$O$1:$P$511,2,0) -> 44 | V3: 44
A4: Steven Stamkos, TB | B4: 78 | C4: 43 | D4: 34 | E4: 78 | F4: 17 | G4: 16 | H4: 1 | I4: 43 | J4: 311 | M4: Steven | N4: Stamkos | O4: =M4&" "&N4 -> Steven Stamkos | P4: 78 | R4: Charlie | S4: Coyle | T4: =R4&" "&S4 -> Charlie Coyle | U4: =VLOOKUP(T4,$O$1:$P$511,2,0) -> 40 | V4: 40
A5: Patrice Bergeron, BOS | B5: 78 | C5: 35 | D5: 36 | E5: 71 | F5: 23 | G5: 14 | H5: 1 | I5: 46 | J5: 307 | M5: Patrice | N5: Bergeron | O5: =M5&" "&N5 -> Patrice Bergeron | P5: 71 | R5: Shayne | S5: Gostisbehe… | T5: =R5&" "&S5 -> Shayne Gostisbehe… | U5: =VLOOKUP(T5,$O$1:$P$511,2,0) -> #N/A | V5: #N/A
A6: Joe Pavelski, SJ | B6: 78 | C6: 42 | D6: 35 | E6: 78 | F6: 19 | G6: 13 | H6: 0 | I6: 28 | J6: 307 | M6: Joe | N6: Pavelski | O6: =M6&" "&N6 -> Joe Pavelski | P6: 78 | R6: Mikael | S6: Granlund | T6: =R6&" "&S6 -> Mikael Granlund | U6: =VLOOKUP(T6,$O$1:$P$511,2,0) -> 42 | V6: 42
A7: Jason Spezza, DAL | B7: 78 | C7: 35 | D7: 37 | E7: 72 | F7: 29 | G7: 16 | H7: 0 | I7: 26 | J7: 297 | M7: Jason | N7: Spezza | O7: =M7&" "&N7 -> Jason Spezza | P7: 72 | R7: Jesse | S7: Puljujarvi | T7: =R7&" "&S7 -> Jesse Puljujarvi | U7: =VLOOKUP(T7,$O$1:$P$511,2,0) -> 34 | V7: 34
A8: John Tavares, NYI | B8: 78 | C8: 37 | D8: 39 | E8: 76 | F8: 0 | G8: 13 | H8: 0 | I8: 44 | J8: 281 | M8: John | N8: Tavares | O8: =M8&" "&N8 -> John Tavares | P8: 76 | R8: Brock | S8: Nelson | T8: =R8&" "&S8 -> Brock Nelson | U8: =VLOOKUP(T8,$O$1:$P$511,2,0) -> 41 | V8: 41
A9: Nicklas Backstrom, WAS | B9: 78 | C9: 21 | D9: 56 | E9: 78 | F9: 24 | G9: 17 | H9: 0 | I9: 43 | J9: 280 | M9: Nicklas | N9: Backstrom | O9: =M9&" "&N9 -> Nicklas Backstrom | P9: 78 | R9: Travis | S9: Zajac | T9: =R9&" "&S9 -> Travis Zajac | U9: =VLOOKUP(T9,$O$1:$P$511,2,0) -> 51 | V9: 51
A10: Ryan Getzlaf, ANA | B10: 78 | C10: 17 | D10: 58 | E10: 75 | F10: 24 | G10: 12 | H10: 0 | I10: 52 | J10: 275 | M10: Ryan | N10: Getzlaf | O10: =M10&" "&N10 -> Ryan Getzlaf | P10: 75 | R10: Pierre-A | S10: Parenteau | T10: =R10&" "&S10 -> Pierre-A Parenteau | U10: =VLOOKUP(T10,$O$1:$P$511,2,0) -> #N/A | V10: #N/A
A11: Anze Kopitar, LA | B11: 78 | C11: 26 | D11: 48 | E11: 75 | F11: 22 | G11: 10 | H11: 1 | I11: 16 | J11: 269 | M11: Anze | N11: Kopitar | O11: =M11&" "&N11 -> Anze Kopitar | P11: 75 | R11: Joe | S11: Colborne | T11: =R11&" "&S11 -> Joe Colborne | U11: =VLOOKUP(T11,$O$1:$P$511,2,0) -> 45 | V11: 45
A12: Claude Giroux, PHI | B12: 78 | C12: 25 | D12: 48 | E12: 73 | F12: 0 | G12: 15 | H12: 1 | I12: 50 | J12: 264 | M12: Claude | N12: Giroux | O12: =M12&" "&N12 -> Claude Giroux | P12: 73 | R12: Teddy | S12: Purcell | T12: =R12&" "&S12 -> Teddy Purcell | U12: =VLOOKUP(T12,$O$1:$P$511,2,0) -> 47 | V12: 47
A13: Jonathan Toews, CHI | B13: 78 | C13: 29 | D13: 34 | E13: 64 | F13: 35 | G13: 5 | H13: 3 | I13: 73 | J13: 264 | M13: Jonathan | N13: Toews | O13: =M13&" "&N13 -> Jonathan Toews | P13: 64 | R13: David | S13: Perron | T13: =R13&" "&S13 -> David Perron | U13: =VLOOKUP(T13,$O$1:$P$511,2,0) -> 42 | V13: 42
A14: Jeff Carter, LA | B14: 78 | C14: 28 | D14: 39 | E14: 67 | F14: 15 | G14: 8 | H14: 1 | I14: 24 | J14: 263 | M14: Jeff | N14: Carter | O14: =M14&" "&N14 -> Jeff Carter | P14: 67 | R14: Artem | S14: Anisimov | T14: =R14&" "&S14 -> Artem Anisimov | U14: =VLOOKUP(T14,$O$1:$P$511,2,0) -> 47 | V14: 47
A15: David Krejci, BOS | B15: 78 | C15: 20 | D15: 53 | E15: 73 | F15: 22 | G15: 12 | H15: 1 | I15: 35 | J15: 261 | M15: David | N15: Krejci | O15: =M15&" "&N15 -> David Krejci | P15: 73 | R15: Nick | S15: Bjugstad | T15: =R15&" "&S15 -> Nick Bjugstad | U15: =VLOOKUP(T15,$O$1:$P$511,2,0) -> 40 | V15: 40
A16: Evgeny Kuznetsov, WAS | B16: 78 | C16: 19 | D16: 52 | E16: 71 | F16: 26 | G16: 9 | H16: 0 | I16: 36 | J16: 261 | M16: Evgeny | N16: Kuznetsov | O16: =M16&" "&N16 -> Evgeny Kuznetsov | P16: 71 | R16: Kevin | S16: Hayes | T16: =R16&" "&S16 -> Kevin Hayes | U16: =VLOOKUP(T16,$O$1:$P$511,2,0) -> 37 | V16: 37
A17: Joe Thornton, SJ | B17: 78 | C17: 17 | D17: 60 | E17: 77 | F17: 20 | G17: 13 | H17: 0 | I17: 53 | J17: 261 | M17: Joe | N17: Thornton | O17: =M17&" "&N17 -> Joe Thornton | P17: 77 | R17: Vladislav | S17: Namestn… | T17: =R17&" "&S17 -> Vladislav Namestn… | U17: =VLOOKUP(T17,$O$1:$P$511,2,0) -> #N/A | V17: #N/A
A18: Logan Couture, SJ | B18: 78 | C18: 26 | D18: 41 | E18: 68 | F18: 8 | G18: 12 | H18: 0 | I18: 32 | J18: 257 | M18: Logan | N18: Couture | O18: =M18&" "&N18 -> Logan Couture | P18: 68 | R18: Pavel | S18: Zacha | T18: =R18&" "&S18 -> Pavel Zacha | U18: =VLOOKUP(T18,$O$1:$P$511,2,0) -> 37 | V18: 37
A19: Ryan Johansen, NSH | B19: 78 | C19: 17 | D19: 46 | E19: 64 | F19: 32 | G19: 13 | H19: 0 | I19: 56 | J19: 257 | M19: Ryan | N19: Johansen | O19: =M19&" "&N19 -> Ryan Johansen | P19: 64 | R19: Alexander | S19: Radulov | T19: =R19&" "&S19 -> Alexander Radulov | U19: =VLOOKUP(T19,$O$1:$P$511,2,0) -> 39 | V19: 39
A20: Mark Scheifele, WPG | B20: 78 | C20: 34 | D20: 36 | E20: 70 | F20: -2 | G20: 8 | H20: 0 | I20: 52 | J20: 248 | M20: Mark | N20: Scheifele | O20: =M20&" "&N20 -> Mark Scheifele | P20: 70 | R20: Jonathan | S20: Drouin | T20: =R20&" "&S20 -> Jonathan Drouin | U20: =VLOOKUP(T20,$O$1:$P$511,2,0) -> 60 | V20: 60
A21: Ryan Kesler, ANA | B21: 78 | C21: 27 | D21: 34 | E21: 62 | F21: 17 | G21: 8 | H21: 0 | I21: 67 | J21: 242 | M21: Ryan | N21: Kesler | O21: =M21&" "&N21 -> Ryan Kesler | P21: 62 | R21: Kyle | S21: Turris | T21: =R21&" "&S21 -> Kyle Turris | U21: =VLOOKUP(T21,$O$1:$P$511,2,0) -> 45 | V21: 45
A22: Tyler Johnson, TB | B22: 78 | C22: 23 | D22: 37 | E22: 60 | F22: 26 | G22: 12 | H22: 0 | I22: 30 | J22: 240 | M22: Tyler | N22: Johnson | O22: =M22&" "&N22 -> Tyler Johnson | P22: 60 | R22: Patrik | S22: Laine | T22: =R22&" "&S22 -> Patrik Laine | U22: =VLOOKUP(T22,$O$1:$P$511,2,0) -> 37 | V22: 37
A23: Derick Brassard, OTT | B23: 78 | C23: 28 | D23: 35 | E23: 63 | F23: 6 | G23: 15 | H23: 0 | I23: 36 | J23: 240 | M23: Derick | N23: Brassard | O23: =M23&" "&N23 -> Derick Brassard | P23: 63 | R23: Zach | S23: Parise | T23: =R23&" "&S23 -> Zach Parise | U23: =VLOOKUP(T23,$O$1:$P$511,2,0) -> 62 | V23: 62
A24: Derek Stepan, NYR | B24: 78 | C24: 26 | D24: 34 | E24: 61 | F24: 13 | G24: 11 | H24: 1 | I24: 22 | J24: 238 | M24: Derek | N24: Stepan | O24: =M24&" "&N24 -> Derek Stepan | P24: 61 | R24: Kristopher | S24: Letang | T24: =R24&" "&S24 -> Kristopher Letang | U24: =VLOOKUP(T24,$O$1:$P$511,2,0) -> #N/A | V24: #N/A
A25: Connor McDavid, EDM | B25: 78 | C25: 28 | D25: 53 | E25: 82 | F25: -25 | G25: 11 | H25: 0 | I25: 29 | J25: 233 | M25: Connor | N25: McDavid | O25: =M25&" "&N25 -> Connor McDavid | P25: 82 | R25: Auston | S25: Matthews | T25: =R25&" "&S25 -> Auston Matthews | U25: =VLOOKUP(T25,$O$1:$P$511,2,0) -> 37 | V25: 37
A26: Brayden Schenn, PHI | B26: 78 | C26: 28 | D26: 35 | E26: 64 | F26: 6 | G26: 11 | H26: 0 | I26: 36 | J26: 232 | M26: Brayden | N26: Schenn | O26: =M26&" "&N26 -> Brayden Schenn | P26: 64 | R26: Ryan | S26: Johansen | T26: =R26&" "&S26 -> Ryan Johansen | U26: =VLOOKUP(T26,$O$1:$P$511,2,0) -> 64 | V26: 64
A27: Alex Galchenyuk, MON | B27: 78 | C27: 32 | D27: 26 | E27: 58 | F27: 9 | G27: 10 | H27: 0 | I27: 22 | J27: 227 | M27: Alex | N27: Galchenyuk | O27: =M27&" "&N27 -> Alex Galchenyuk | P27: 58 | R27: Vincent | S27: Trocheck | T27: =R27&" "&S27 -> Vincent Trocheck | U27: =VLOOKUP(T27,$O$1:$P$511,2,0) -> 55 | V27: 55
A28: Antoine Vermette, ANA | B28: 78 | C28: 22 | D28: 26 | E28: 48 | F28: 38 | G28: 9 | H28: 0 | I28: 86 | J28: 225 | M28: Antoine | N28: Vermette | O28: =M28&" "&N28 -> Antoine Vermette | P28: 48 | R28: Alex | S28: Galchenyuk | T28: =R28&" "&S28 -> Alex Galchenyuk | U28: =VLOOKUP(T28,$O$1:$P$511,2,0) -> 58 | V28: 58
A29: Matt Duchene, COL | B29: 78 | C29: 34 | D29: 30 | E29: 64 | F29: -7 | G29: 8 | H29: 0 | I29: 26 | J29: 218 | M29: Matt | N29: Duchene | O29: =M29&" "&N29 -> Matt Duchene | P29: 64 | R29: Andrew | S29: Ladd | T29: =R29&" "&S29 -> Andrew Ladd | U29: =VLOOKUP(T29,$O$1:$P$511,2,0) -> 49 | V29: 49
A30: Sean Monahan, CGY | B30: 78 | C30: 27 | D30: 32 | E30: 60 | F30: 1 | G30: 11 | H30: 0 | I30: 18 | J30: 216 | M30: Sean | N30: Monahan | O30: =M30&" "&N30 -> Sean Monahan | P30: 60 | R30: Bobby | S30: Ryan | T30: =R30&" "&S30 -> Bobby Ryan | U30: =VLOOKUP(T30,$O$1:$P$511,2,0) -> 60 | V30: 60
A31: Mika Zibanejad, NYR | B31: 78 | C31: 22 | D31: 32 | E31: 54 | F31: 23 | G31: 8 | H31: 1 | I31: 15 | J31: 212 | M31: Mika | N31: Zibanejad | O31: =M31&" "&N31 -> Mika Zibanejad | P31: 54 | R31: Jaden | S31: Schwartz | T31: =R31&" "&S31 -> Jaden Schwartz | U31: =VLOOKUP(T31,$O$1:$P$511,2,0) -> 49 | V31: 49
A32: Aleksander Barkov, FLA | B32: 78 | C32: 32 | D32: 32 | E32: 65 | F32: -22 | G32: 10 | H32: 1 | I32: 11 | J32: 210 | M32: Aleksander | N32: Barkov | O32: =M32&" "&N32 -> Aleksander Barkov | P32: 65 | R32: Artemi | S32: Panarin | T32: =R32&" "&S32 -> Artemi Panarin | U32: =VLOOKUP(T32,$O$1:$P$511,2,0) -> 84 | V32: 84
A33: Tomas Plekanec, MON | B33: 78 | C33: 15 | D33: 40 | E33: 55 | F33: 15 | G33: 8 | H33: 0 | I33: 40 | J33: 207 | M33: Tomas | N33: Plekanec | O33: =M33&" "&N33 -> Tomas Plekanec | P33: 55 | R33: Tyler | S33: Johnson | T33: =R33&" "&S33 -> Tyler Johnson | U33: =VLOOKUP(T33,$O$1:$P$511,2,0) -> 60 | V33: 60
A34: Nathan MacKinnon, COL | B34: 78 | C34: 24 | D34: 33 | E34: 58 | F34: -12 | G34: 9 | H34: 0 | I34: 24 | J34: 207 | M34: Nathan | N34: MacKinnon | O34: =M34&" "&N34 -> Nathan MacKinnon | P34: 58 | R34: Milan | S34: Lucic | T34: =R34&" "&S34 -> Milan Lucic | U34: =VLOOKUP(T34,$O$1:$P$511,2,0) -> 49 | V34: 49
A35: Rickard Rakell, ANA | B35: 78 | C35: 25 | D35: 27 | E35: 53 | F35: 15 | G35: 5 | H35: 0 | I35: 17 | J35: 205 | M35: Rickard | N35: Rakell | O35: =M35&" "&N35 -> Rickard Rakell | P35: 53 | R35: Aleksander | S35: Barkov | T35: =R35&" "&S35 -> Aleksander Barkov | U35: =VLOOKUP(T35,$O$1:$P$511,2,0) -> 65 | V35: 65
A36: Nazem Kadri, TOR | B36: 78 | C36: 20 | D36: 30 | E36: 51 | F36: -19 | G36: 9 | H36: 0 | I36: 94 | J36: 200 | M36: Nazem | N36: Kadri | O36: =M36&" "&N36 -> Nazem Kadri | P36: 51 | R36: Filip | S36: Forsberg | T36: =R36&" "&S36 -> Filip Forsberg | U36: =VLOOKUP(T36,$O$1:$P$511,2,0) -> 64 | V36: 64
... A39: Paul Stastny, STL | B39: 78 | C39: 13 | D39: 47 | E39: 60 | F39: 7 | G39: 8 | H39: 0 | I39: 42 | J39: 198 | M39: Paul | N39: Stastny | O39: =M39&" "&N39 -> Paul Stastny | P39: 60 | R39: Sidney | S39: Crosby | T39: =R39&" "&S39 -> Sidney Crosby | U39: =VLOOKUP(T39,$O$1:$P$511,2,0) -> 89 | V39: 89
A40: Ryan Spooner, BOS | B40: 78 | C40: 14 | D40: 38 | E40: 52 | F40: 13 | G40: 10 | H40: 0 | I40: 33 | J40: 198 | M40: Ryan | N40: Spooner | O40: =M40&" "&N40 -> Ryan Spooner | P40: 52 | R40: Ryan | S40: Nugent-Hopki… | T40: =R40&" "&S40 -> Ryan Nugent-Hopki… | U40: =VLOOKUP(T40,$O$1:$P$511,2,0) -> #N/A | V40: #N/A
A41: Nick Bonino, PIT | B41: 78 | C41: 13 | D41: 34 | E41: 48 | F41: 37 | G41: 2 | H41: 1 | I41: 47 | J41: 196 | M41: Nick | N41: Bonino | O41: =M41&" "&N41 -> Nick Bonino | P41: 48 | R41: Thomas | S41: Vanek | T41: =R41&" "&S41 -> Thomas Vanek | U41: =VLOOKUP(T41,$O$1:$P$511,2,0) -> 44 | V41: 44
A42: Artem Anisimov, CHI | B42: 78 | C42: 24 | D42: 22 | E42: 47 | F42: 29 | G42: 5 | H42: 2 | I42: 15 | J42: 193 | M42: Artem | N42: Anisimov | O42: =M42&" "&N42 -> Artem Anisimov | P42: 47 | R42: Sean | S42: Couturier | T42: =R42&" "&S42 -> Sean Couturier | U42: =VLOOKUP(T42,$O$1:$P$511,2,0) -> 52 | V42: 52
...
