Workbook

Sheet Liste
P1: Différence
A2: Colonne1 | B2: Prenom | C2: Nom | D2: Colonne2 | E2: Âge | F2: Colonne32 | G2: Lepool.com | H2: HM | I2: Pool Pro | J2: HN | K2: ESPN | L2: CBS | M2: Moyenne | N2: MJ | O2: Final | P2: Lepool.com2 | Q2: HM2 | R2: Pool Pro2 | S2: ESPN2 | T2: CBS2 | U2: Moyenne2
B3: Patrik | C3: Laine | D3: =Tableau1[[#This Row],[Prenom]]&" "&Tableau1[[#This Row],[Nom]] -> Patrik Laine | E3: =VLOOKUP(Tableau1[[#This Row],[Colonne2]],'BCP stats'!$C$6:$D$305,2,FALSE) -> 18 | G3: 60 | H3: 48 | J3: 46 | K3: 43 | L3: 37 | M3: =AVERAGE(Tableau1[[#This Row],[Lepool.com]:[CBS]]) -> 46.8 | N3: =VLOOKUP(Tableau1[[#This Row],[Colonne2]],Final!$B$3:$I$302,4,FALSE) -> 73 | O3: =VLOOKUP(Tableau1[[#This Row],[Colonne2]],Final!$B$3:$I$302,7,FALSE) -> 64 | P3: =Tableau1[[#This Row],[Final]]-Tableau1[[#This Row],[Lepool.com]] -> 4 | Q3: =Tableau1[[#This Row],[Final]]-Tableau1[[#This Row],[HM]] -> 16 | R3: =Tableau1[[#This Row],[Final]]-Tableau1[[#This Row],[Pool Pro]] -> 64 | S3: =Tableau1[[#This Row],[Final]]-Tableau1[[#This Row],[ESPN]] -> 21 | T3: =Tableau1[[#This Row],[Final]]-Tableau1[[#This Row],[CBS]] -> 27 | U3: =Tableau1[[#This Row],[Final]]-Tableau1[[#This Row],[Moyenne]] -> 17.2
B4: Mitchell | C4: Marner | D4: =Tableau1[[#This Row],[Prenom]]&" "&Tableau1[[#This Row],[Nom]] -> Mitchell Marner | E4: =VLOOKUP(Tableau1[[#This Row],[Colonne2]],'BCP stats'!$C$6:$D$305,2,FALSE) -> 19 | H4: 48 | J4: 49 | L4: 36 | M4: =AVERAGE(Tableau1[[#This Row],[Lepool.com]:[CBS]]) -> 44.333333 | N4: =VLOOKUP(Tableau1[[#This Row],[Colonne2]],Final!$B$3:$I$302,4,FALSE) -> 77 | O4: =VLOOKUP(Tableau1[[#This Row],[Colonne2]],Final!$B$3:$I$302,7,FALSE) -> 61 | P4: =Tableau1[[#This Row],[Final]]-Tableau1[[#This Row],[Lepool.com]] -> 61 | Q4: =Tableau1[[#This Row],[Final]]-Tableau1[[#This Row],[HM]] -> 13 | R4: =Tableau1[[#This Row],[Final]]-Tableau1[[#This Row],[Pool Pro]] -> 61 | S4: =Tableau1[[#This Row],[Final]]-Tableau1[[#This Row],[ESPN]] -> 61 | T4: =Tableau1[[#This Row],[Final]]-Tableau1[[#This Row],[CBS]] -> 25 | U4: =Tableau1[[#This Row],[Final]]-Tableau1[[#This Row],[Moyenne]] -> 16.666667
B5: Connor | C5: McDavid | D5: =Tableau1[[#This Row],[Prenom]]&" "&Tableau1[[#This Row],[Nom]] -> Connor McDavid | E5: =VLOOKUP(Tableau1[[#This Row],[Colonne2]],'BCP stats'!$C$6:$D$305,2,FALSE) -> 19 | G5: 90 | H5: 87 | I5: 85 | J5: 96 | K5: 84 | L5: 82 | M5: =AVERAGE(Tableau1[[#This Row],[Lepool.com]:[CBS]]) -> 87.333333 | N5: =VLOOKUP(Tableau1[[#This Row],[Colonne2]],Final!$B$3:$I$302,4,FALSE) -> 82 | O5: =VLOOKUP(Tableau1[[#This Row],[Colonne2]],Final!$B$3:$I$302,7,FALSE) -> 100 | P5: =Tableau1[[#This Row],[Final]]-Tableau1[[#This Row],[Lepool.com]] -> 10 | Q5: =Tableau1[[#This Row],[Final]]-Tableau1[[#This Row],[HM]] -> 13 | R5: =Tableau1[[#This Row],[Final]]-Tableau1[[#This Row],[Pool Pro]] -> 15 | S5: =Tableau1[[#This Row],[Final]]-Tableau1[[#This Row],[ESPN]] -> 16 | T5: =Tableau1[[#This Row],[Final]]-Tableau1[[#This Row],[CBS]] -> 18 | U5: =Tableau1[[#This Row],[Final]]-Tableau1[[#This Row],[Moyenne]] -> 12.666667
B6: Auston | C6: Matthews | D6: =Tableau1[[#This Row],[Prenom]]&" "&Tableau1[[#This Row],[Nom]] -> Auston Matthews | E6: =VLOOKUP(Tableau1[[#This Row],[Colonne2]],'BCP stats'!$C$6:$D$305,2,FALSE) -> 19 | G6: 67 | H6: 52 | J6: 65 | K6: 56 | L6: 37 | M6: =AVERAGE(Tableau1[[#This Row],[Lepool.com]:[CBS]]) -> 55.4 | N6: =VLOOKUP(Tableau1[[#This Row],[Colonne2]],Final!$B$3:$I$302,4,FALSE) -> 82 | O6: =VLOOKUP(Tableau1[[#This Row],[Colonne2]],Final!$B$3:$I$302,7,FALSE) -> 69 | P6: =Tableau1[[#This Row],[Final]]-Tableau1[[#This Row],[Lepool.com]] -> 2 | Q6: =Tableau1[[#This Row],[Final]]-Tableau1[[#This Row],[HM]] -> 17 | R6: =Tableau1[[#This Row],[Final]]-Tableau1[[#This Row],[Pool Pro]] -> 69 | S6: =Tableau1[[#This Row],[Final]]-Tableau1[[#This Row],[ESPN]] -> 13 | T6: =Tableau1[[#This Row],[Final]]-Tableau1[[#This Row],[CBS]] -> 32 | U6: =Tableau1[[#This Row],[Final]]-Tableau1[[#This Row],[Moyenne]] -> 13.6
B7: Dylan | C7: Larkin | D7: =Tableau1[[#This Row],[Prenom]]&" "&Tableau1[[#This Row],[Nom]] -> Dylan Larkin | E7: =VLOOKUP(Tableau1[[#This Row],[Colonne2]],'BCP stats'!$C$6:$D$305,2,FALSE) -> 20 | G7: 58 | H7: 52 | I7: 53 | J7: 55 | K7: 54 | L7: 47 | M7: =AVERAGE(Tableau1[[#This Row],[Lepool.com]:[CBS]]) -> 53.166667 | N7: =VLOOKUP(Tableau1[[#This Row],[Colonne2]],Final!$B$3:$I$302,4,FALSE) -> 80 | O7: =VLOOKUP(Tableau1[[#This Row],[Colonne2]],Final!$B$3:$I$302,7,FALSE) -> 32 | P7: =Tableau1[[#This Row],[Final]]-Tableau1[[#This Row],[Lepool.com]] -> -26 | Q7: =Tableau1[[#This Row],[Final]]-Tableau1[[#This Row],[HM]] -> -20 | R7: =Tableau1[[#This Row],[Final]]-Tableau1[[#This Row],[Pool Pro]] -> -21 | S7: =Tableau1[[#This Row],[Final]]-Tableau1[[#This Row],[ESPN]] -> -22 | T7: =Tableau1[[#This Row],[Final]]-Tableau1[[#This Row],[CBS]] -> -15 | U7: =Tableau1[[#This Row],[Final]]-Tableau1[[#This Row],[Moyenne]] -> -21.166667
B8: Sam | C8: Bennett | D8: =Tableau1[[#This Row],[Prenom]]&" "&Tableau1[[#This Row],[Nom]] -> Sam Bennett | E8: =VLOOKUP(Tableau1[[#This Row],[Colonne2]],'BCP stats'!$C$6:$D$305,2,FALSE) -> 20 | G8: 48 | H8: 46 | I8: 51 | J8: 54 | K8: 48 | L8: 36 | M8: =AVERAGE(Tableau1[[#This Row],[Lepool.com]:[CBS]]) -> 47.166667 | N8: =VLOOKUP(Tableau1[[#This Row],[Colonne2]],Final!$B$3:$I$302,4,FALSE) -> 81 | O8: =VLOOKUP(Tableau1[[#This Row],[Colonne2]],Final!$B$3:$I$302,7,FALSE) -> 26 | P8: =Tableau1[[#This Row],[Final]]-Tableau1[[#This Row],[Lepool.com]] -> -22 | Q8: =Tableau1[[#This Row],[Final]]-Tableau1[[#This Row],[HM]] -> -20 | R8: =Tableau1[[#This Row],[Final]]-Tableau1[[#This Row],[Pool Pro]] -> -25 | S8: =Tableau1[[#This Row],[Final]]-Tableau1[[#This Row],[ESPN]] -> -22 | T8: =Tableau1[[#This Row],[Final]]-Tableau1[[#This Row],[CBS]] -> -10 | U8: =Tableau1[[#This Row],[Final]]-Tableau1[[#This Row],[Moyenne]] -> -21.166667
B9: Robby | C9: Fabbri | D9: =Tableau1[[#This Row],[Prenom]]&" "&Tableau1[[#This Row],[Nom]] -> Robby Fabbri | E9: =VLOOKUP(Tableau1[[#This Row],[Colonne2]],'BCP stats'!$C$6:$D$305,2,FALSE) -> 20 | G9: 48 | H9: 48 | I9: 51 | J9: 54 | K9: 49 | L9: 50 | M9: =AVERAGE(Tableau1[[#This Row],[Lepool.com]:[CBS]]) -> 50 | N9: =VLOOKUP(Tableau1[[#This Row],[Colonne2]],Final!$B$3:$I$302,4,FALSE) -> 51 | O9: =VLOOKUP(Tableau1[[#This Row],[Colonne2]],Final!$B$3:$I$302,7,FALSE) -> 29 | P9: =Tableau1[[#This Row],[Final]]-Tableau1[[#This Row],[Lepool.com]] -> -19 | Q9: =Tableau1[[#This Row],[Final]]-Tableau1[[#This Row],[HM]] -> -19 | R9: =Tableau1[[#This Row],[Final]]-Tableau1[[#This Row],[Pool Pro]] -> -22 | S9: =Tableau1[[#This Row],[Final]]-Tableau1[[#This Row],[ESPN]] -> -20 | T9: =Tableau1[[#This Row],[Final]]-Tableau1[[#This Row],[CBS]] -> -21 | U9: =Tableau1[[#This Row],[Final]]-Tableau1[[#This Row],[Moyenne]] -> -21
B10: Jack | C10: Eichel | D10: =Tableau1[[#This Row],[Prenom]]&" "&Tableau1[[#This Row],[Nom]] -> Jack Eichel | E10: =VLOOKUP(Tableau1[[#This Row],[Colonne2]],'BCP stats'!$C$6:$D$305,2,FALSE) -> 20 | G10: 68 | H10: 65 | I10: 66 | J10: 63 | K10: 64 | L10: 54 | M10: =AVERAGE(Tableau1[[#This Row],[Lepool.com]:[CBS]]) -> 63.333333 | N10: =VLOOKUP(Tableau1[[#This Row],[Colonne2]],Final!$B$3:$I$302,4,FALSE) -> 61 | O10: =VLOOKUP(Tableau1[[#This Row],[Colonne2]],Final!$B$3:$I$302,7,FALSE) -> 57 | P10: =Tableau1[[#This Row],[Final]]-Tableau1[[#This Row],[Lepool.com]] -> -11 | Q10: =Tableau1[[#This Row],[Final]]-Tableau1[[#This Row],[HM]] -> -8 | R10: =Tableau1[[#This Row],[Final]]-Tableau1[[#This Row],[Pool Pro]] -> -9 | S10: =Tableau1[[#This Row],[Final]]-Tableau1[[#This Row],[ESPN]] -> -7 | T10: =Tableau1[[#This Row],[Final]]-Tableau1[[#This Row],[CBS]] -> 3 | U10: =Tableau1[[#This Row],[Final]]-Tableau1[[#This Row],[Moyenne]] -> -6.3333333
B11: Nikolaj | C11: Ehlers | D11: =Tableau1[[#This Row],[Prenom]]&" "&Tableau1[[#This Row],[Nom]] -> Nikolaj Ehlers | E11: =VLOOKUP(Tableau1[[#This Row],[Colonne2]],'BCP stats'!$C$6:$D$305,2,FALSE) -> 20 | G11: 50 | H11: 49 | I11: 46 | J11: 55 | K11: 48 | L11: 42 | M11: =AVERAGE(Tableau1[[#This Row],[Lepool.com]:[CBS]]) -> 48.333333 | N11: =VLOOKUP(Tableau1[[#This Row],[Colonne2]],Final!$B$3:$I$302,4,FALSE) -> 82 | O11: =VLOOKUP(Tableau1[[#This Row],[Colonne2]],Final!$B$3:$I$302,7,FALSE) -> 64 | P11: =Tableau1[[#This Row],[Final]]-Tableau1[[#This Row],[Lepool.com]] -> 14 | Q11: =Tableau1[[#This Row],[Final]]-Tableau1[[#This Row],[HM]] -> 15 | R11: =Tableau1[[#This Row],[Final]]-Tableau1[[#This Row],[Pool Pro]] -> 18 | S11: =Tableau1[[#This Row],[Final]]-Tableau1[[#This Row],[ESPN]] -> 16 | T11: =Tableau1[[#This Row],[Final]]-Tableau1[[#This Row],[CBS]] -> 22 | U11: =Tableau1[[#This Row],[Final]]-Tableau1[[#This Row],[Moyenne]] -> 15.666667
B12: William | C12: Nylander | D12: =Tableau1[[#This Row],[Prenom]]&" "&Tableau1[[#This Row],[Nom]] -> William Nylander | E12: =VLOOKUP(Tableau1[[#This Row],[Colonne2]],'BCP stats'!$C$6:$D$305,2,FALSE) -> 20 | H12: 41 | I12: 42 | J12: 42 | K12: 47 | L12: 52 | M12: =AVERAGE(Tableau1[[#This Row],[Lepool.com]:[CBS]]) -> 44.8 | N12: =VLOOKUP(Tableau1[[#This Row],[Colonne2]],Final!$B$3:$I$302,4,FALSE) -> 81 | O12: =VLOOKUP(Tableau1[[#This Row],[Colonne2]],Final!$B$3:$I$302,7,FALSE) -> 61 | P12: =Tableau1[[#This Row],[Final]]-Tableau1[[#This Row],[Lepool.com]] -> 61 | Q12: =Tableau1[[#This Row],[Final]]-Tableau1[[#This Row],[HM]] -> 20 | R12: =Tableau1[[#This Row],[Final]]-Tableau1[[#This Row],[Pool Pro]] -> 19 | S12: =Tableau1[[#This Row],[Final]]-Tableau1[[#This Row],[ESPN]] -> 14 | T12: =Tableau1[[#This Row],[Final]]-Tableau1[[#This Row],[CBS]] -> 9 | U12: =Tableau1[[#This Row],[Final]]-Tableau1[[#This Row],[Moyenne]] -> 16.2
B13: David | C13: Pastrnak | D13: =Tableau1[[#This Row],[Prenom]]&" "&Tableau1[[#This Row],[Nom]] -> David Pastrnak | E13: =VLOOKUP(Tableau1[[#This Row],[Colonne2]],'BCP stats'!$C$6:$D$305,2,FALSE) -> 20 | H13: 48 | I13: 47 | J13: 52 | K13: 43 | L13: 42 | M13: =AVERAGE(Tableau1[[#This Row],[Lepool.com]:[CBS]]) -> 46.4 | N13: =VLOOKUP(Tableau1[[#This Row],[Colonne2]],Final!$B$3:$I$302,4,FALSE) -> 75 | O13: =VLOOKUP(Tableau1[[#This Row],[Colonne2]],Final!$B$3:$I$302,7,FALSE) -> 70 | P13: =Tableau1[[#This Row],[Final]]-Tableau1[[#This Row],[Lepool.com]] -> 70 | Q13: =Tableau1[[#This Row],[Final]]-Tableau1[[#This Row],[HM]] -> 22 | R13: =Tableau1[[#This Row],[Final]]-Tableau1[[#This Row],[Pool Pro]] -> 23 | S13: =Tableau1[[#This Row],[Final]]-Tableau1[[#This Row],[ESPN]] -> 27 | T13: =Tableau1[[#This Row],[Final]]-Tableau1[[#This Row],[CBS]] -> 28 | U13: =Tableau1[[#This Row],[Final]]-Tableau1[[#This Row],[Moyenne]] -> 23.6
B14: Aleksander | C14: Barkov | D14: =Tableau1[[#This Row],[Prenom]]&" "&Tableau1[[#This Row],[Nom]] -> Aleksander Barkov | E14: =VLOOKUP(Tableau1[[#This Row],[Colonne2]],'BCP stats'!$C$6:$D$305,2,FALSE) -> 21 | G14: 73 | H14: 71 | I14: 66 | J14: 71 | K14: 59 | L14: 65 | M14: =AVERAGE(Tableau1[[#This Row],[Lepool.com]:[CBS]]) -> 67.5 | N14: =VLOOKUP(Tableau1[[#This Row],[Colonne2]],Final!$B$3:$I$302,4,FALSE) -> 61 | O14: =VLOOKUP(Tableau1[[#This Row],[Colonne2]],Final!$B$3:$I$302,7,FALSE) -> 52 | P14: =Tableau1[[#This Row],[Final]]-Tableau1[[#This Row],[Lepool.com]] -> -21 | Q14: =Tableau1[[#This Row],[Final]]-Tableau1[[#This Row],[HM]] -> -19 | R14: =Tableau1[[#This Row],[Final]]-Tableau1[[#This Row],[Pool Pro]] -> -14 | S14: =Tableau1[[#This Row],[Final]]-Tableau1[[#This Row],[ESPN]] -> -7 | T14: =Tableau1[[#This Row],[Final]]-Tableau1[[#This Row],[CBS]] -> -13 | U14: =Tableau1[[#This Row],[Final]]-Tableau1[[#This Row],[Moyenne]] -> -15.5
B15: Max | C15: Domi | D15: =Tableau1[[#This Row],[Prenom]]&" "&Tableau1[[#This Row],[Nom]] -> Max Domi | E15: =VLOOKUP(Tableau1[[#This Row],[Colonne2]],'BCP stats'!$C$6:$D$305,2,FALSE) -> 21 | G15: 61 | H15: 55 | I15: 61 | J15: 59 | K15: 58 | L15: 51 | M15: =AVERAGE(Tableau1[[#This Row],[Lepool.com]:[CBS]]) -> 57.5 | N15: =VLOOKUP(Tableau1[[#This Row],[Colonne2]],Final!$B$3:$I$302,4,FALSE) -> 59 | O15: =VLOOKUP(Tableau1[[#This Row],[Colonne2]],Final!$B$3:$I$302,7,FALSE) -> 38 | P15: =Tableau1[[#This Row],[Final]]-Tableau1[[#This Row],[Lepool.com]] -> -23 | Q15: =Tableau1[[#This Row],[Final]]-Tableau1[[#This Row],[HM]] -> -17 | R15: =Tableau1[[#This Row],[Final]]-Tableau1[[#This Row],[Pool Pro]] -> -23 | S15: =Tableau1[[#This Row],[Final]]-Tableau1[[#This Row],[ESPN]] -> -20 | T15: =Tableau1[[#This Row],[Final]]-Tableau1[[#This Row],[CBS]] -> -13 | U15: =Tableau1[[#This Row],[Final]]-Tableau1[[#This Row],[Moyenne]] -> -19.5
B16: Nathan | C16: MacKinnon | D16: =Tableau1[[#This Row],[Prenom]]&" "&Tableau1[[#This Row],[Nom]] -> Nathan MacKinnon | E16: =VLOOKUP(Tableau1[[#This Row],[Colonne2]],'BCP stats'!$C$6:$D$305,2,FALSE) -> 21 | G16: 64 | H16: 61 | I16: 62 | J16: 60 | K16: 53 | L16: 58 | M16: =AVERAGE(Tableau1[[#This Row],[Lepool.com]:[CBS]]) -> 59.666667 | N16: =VLOOKUP(Tableau1[[#This Row],[Colonne2]],Final!$B$3:$I$302,4,FALSE) -> 82 | O16: =VLOOKUP(Tableau1[[#This Row],[Colonne2]],Final!$B$3:$I$302,7,FALSE) -> 53 | P16: =Tableau1[[#This Row],[Final]]-Tableau1[[#This Row],[Lepool.com]] -> -11 | Q16: =Tableau1[[#This Row],[Final]]-Tableau1[[#This Row],[HM]] -> -8 | R16: =Tableau1[[#This Row],[Final]]-Tableau1[[#This Row],[Pool Pro]] -> -9 | S16: =Tableau1[[#This Row],[Final]]-Tableau1[[#This Row],[ESPN]] -> 0 | T16: =Tableau1[[#This Row],[Final]]-Tableau1[[#This Row],[CBS]] -> -5 | U16: =Tableau1[[#This Row],[Final]]-Tableau1[[#This Row],[Moyenne]] -> -6.6666667
B17: Jonathan | C17: Drouin | D17: =Tableau1[[#This Row],[Prenom]]&" "&Tableau1[[#This Row],[Nom]] -> Jonathan Drouin | E17: =VLOOKUP(Tableau1[[#This Row],[Colonne2]],'BCP stats'!$C$6:$D$305,2,FALSE) -> 21 | G17: 49 | H17: 59 | I17: 62 | J17: 63 | K17: 43 | L17: 60 | M17: =AVERAGE(Tableau1[[#This Row],[Lepool.com]:[CBS]]) -> 56 | N17: =VLOOKUP(Tableau1[[#This Row],[Colonne2]],Final!$B$3:$I$302,4,FALSE) -> 73 | O17: =VLOOKUP(Tableau1[[#This Row],[Colonne2]],Final!$B$3:$I$302,7,FALSE) -> 53 | P17: =Tableau1[[#This Row],[Final]]-Tableau1[[#This Row],[Lepool.com]] -> 4 | Q17: =Tableau1[[#This Row],[Final]]-Tableau1[[#This Row],[HM]] -> -6 | R17: =Tableau1[[#This Row],[Final]]-Tableau1[[#This Row],[Pool Pro]] -> -9 | S17: =Tableau1[[#This Row],[Final]]-Tableau1[[#This Row],[ESPN]] -> 10 | T17: =Tableau1[[#This Row],[Final]]-Tableau1[[#This Row],[CBS]] -> -7 | U17: =Tableau1[[#This Row],[Final]]-Tableau1[[#This Row],[Moyenne]] -> -3
B18: Sam | C18: Reinhart | D18: =Tableau1[[#This Row],[Prenom]]&" "&Tableau1[[#This Row],[Nom]] -> Sam Reinhart | E18: =VLOOKUP(Tableau1[[#This Row],[Colonne2]],'BCP stats'!$C$6:$D$305,2,FALSE) -> 21 | G18: 49 | H18: 50 | I18: 47 | J18: 58 | K18: 46 | L18: 41 | M18: =AVERAGE(Tableau1[[#This Row],[Lepool.com]:[CBS]]) -> 48.5 | N18: =VLOOKUP(Tableau1[[#This Row],[Colonne2]],Final!$B$3:$I$302,4,FALSE) -> 79 | O18: =VLOOKUP(Tableau1[[#This Row],[Colonne2]],Final!$B$3:$I$302,7,FALSE) -> 47 | P18: =Tableau1[[#This Row],[Final]]-Tableau1[[#This Row],[Lepool.com]] -> -2 | Q18: =Tableau1[[#This Row],[Final]]-Tableau1[[#This Row],[HM]] -> -3 | R18: =Tableau1[[#This Row],[Final]]-Tableau1[[#This Row],[Pool Pro]] -> 0 | S18: =Tableau1[[#This Row],[Final]]-Tableau1[[#This Row],[ESPN]] -> 1 | T18: =Tableau1[[#This Row],[Final]]-Tableau1[[#This Row],[CBS]] -> 6 | U18: =Tableau1[[#This Row],[Final]]-Tableau1[[#This Row],[Moyenne]] -> -1.5
B19: Bo | C19: Horvat | D19: =Tableau1[[#This Row],[Prenom]]&" "&Tableau1[[#This Row],[Nom]] -> Bo Horvat | E19: =VLOOKUP(Tableau1[[#This Row],[Colonne2]],'BCP stats'!$C$6:$D$305,2,FALSE) -> 21 | G19: 49 | H19: 44 | I19: 48 | J19: 53 | L19: 44 | M19: =AVERAGE(Tableau1[[#This Row],[Lepool.com]:[CBS]]) -> 47.6 | N19: =VLOOKUP(Tableau1[[#This Row],[Colonne2]],Final!$B$3:$I$302,4,FALSE) -> 81 | O19: =VLOOKUP(Tableau1[[#This Row],[Colonne2]],Final!$B$3:$I$302,7,FALSE) -> 52 | P19: =Tableau1[[#This Row],[Final]]-Tableau1[[#This Row],[Lepool.com]] -> 3 | Q19: =Tableau1[[#This Row],[Final]]-Tableau1[[#This Row],[HM]] -> 8 | R19: =Tableau1[[#This Row],[Final]]-Tableau1[[#This Row],[Pool Pro]] -> 4 | S19: =Tableau1[[#This Row],[Final]]-Tableau1[[#This Row],[ESPN]] -> 52 | T19: =Tableau1[[#This Row],[Final]]-Tableau1[[#This Row],[CBS]] -> 8 | U19: =Tableau1[[#This Row],[Final]]-Tableau1[[#This Row],[Moyenne]] -> 4.4
B20: Leon | C20: Draisaitl | D20: =Tableau1[[#This Row],[Prenom]]&" "&Tableau1[[#This Row],[Nom]] -> Leon Draisaitl | E20: =VLOOKUP(Tableau1[[#This Row],[Colonne2]],'BCP stats'!$C$6:$D$305,2,FALSE) -> 21 | G20: 53 | H20: 58 | I20: 60 | J20: 52 | K20: 56 | L20: 57 | M20: =AVERAGE(Tableau1[[#This Row],[Lepool.com]:[CBS]]) -> 56 | N20: =VLOOKUP(Tableau1[[#This Row],[Colonne2]],Final!$B$3:$I$302,4,FALSE) -> 82 | O20: =VLOOKUP(Tableau1[[#This Row],[Colonne2]],Final!$B$3:$I$302,7,FALSE) -> 77 | P20: =Tableau1[[#This Row],[Final]]-Tableau1[[#This Row],[Lepool.com]] -> 24 | Q20: =Tableau1[[#This Row],[Final]]-Tableau1[[#This Row],[HM]] -> 19 | R20: =Tableau1[[#This Row],[Final]]-Tableau1[[#This Row],[Pool Pro]] -> 17 | S20: =Tableau1[[#This Row],[Final]]-Tableau1[[#This Row],[ESPN]] -> 21 | T20: =Tableau1[[#This Row],[Final]]-Tableau1[[#This Row],[CBS]] -> 20 | U20: =Tableau1[[#This Row],[Final]]-Tableau1[[#This Row],[Moyenne]] -> 21
B21: Alex | C21: Galchenyuk | D21: =Tableau1[[#This Row],[Prenom]]&" "&Tableau1[[#This Row],[Nom]] -> Alex Galchenyuk | E21: =VLOOKUP(Tableau1[[#This Row],[Colonne2]],'BCP stats'!$C$6:$D$305,2,FALSE) -> 22 | G21: 64 | H21: 61 | I21: 62 | J21: 64 | K21: 48 | L21: 58 | M21: =AVERAGE(Tableau1[[#This Row],[Lepool.com]:[CBS]]) -> 59.5 | N21: =VLOOKUP(Tableau1[[#This Row],[Colonne2]],Final!$B$3:$I$302,4,FALSE) -> 61 | O21: =VLOOKUP(Tableau1[[#This Row],[Colonne2]],Final!$B$3:$I$302,7,FALSE) -> 44 | P21: =Tableau1[[#This Row],[Final]]-Tableau1[[#This Row],[Lepool.com]] -> -20 | Q21: =Tableau1[[#This Row],[Final]]-Tableau1[[#This Row],[HM]] -> -17 | R21: =Tableau1[[#This Row],[Final]]-Tableau1[[#This Row],[Pool Pro]] -> -18 | S21: =Tableau1[[#This Row],[Final]]-Tableau1[[#This Row],[ESPN]] -> -4 | T21: =Tableau1[[#This Row],[Final]]-Tableau1[[#This Row],[CBS]] -> -14 | U21: =Tableau1[[#This Row],[Final]]-Tableau1[[#This Row],[Moyenne]] -> -15.5
B22: Filip | C22: Forsberg | D22: =Tableau1[[#This Row],[Prenom]]&" "&Tableau1[[#This Row],[Nom]] -> Filip Forsberg | E22: =VLOOKUP(Tableau1[[#This Row],[Colonne2]],'BCP stats'!$C$6:$D$305,2,FALSE) -> 22 | G22: 72 | H22: 68 | I22: 67 | J22: 65 | K22: 57 | L22: 64 | M22: =AVERAGE(Tableau1[[#This Row],[Lepool.com]:[CBS]]) -> 65.5 | N22: =VLOOKUP(Tableau1[[#This Row],[Colonne2]],Final!$B$3:$I$302,4,FALSE) -> 82 | O22: =VLOOKUP(Tableau1[[#This Row],[Colonne2]],Final!$B$3:$I$302,7,FALSE) -> 58 | P22: =Tableau1[[#This Row],[Final]]-Tableau1[[#This Row],[Lepool.com]] -> -14 | Q22: =Tableau1[[#This Row],[Final]]-Tableau1[[#This Row],[HM]] -> -10 | R22: =Tableau1[[#This Row],[Final]]-Tableau1[[#This Row],[Pool Pro]] -> -9 | S22: =Tableau1[[#This Row],[Final]]-Tableau1[[#This Row],[ESPN]] -> 1 | T22: =Tableau1[[#This Row],[Final]]-Tableau1[[#This Row],[CBS]] -> -6 | U22: =Tableau1[[#This Row],[Final]]-Tableau1[[#This Row],[Moyenne]] -> -7.5
B23: Sean | C23: Monahan | D23: =Tableau1[[#This Row],[Prenom]]&" "&Tableau1[[#This Row],[Nom]] -> Sean Monahan | E23: =VLOOKUP(Tableau1[[#This Row],[Colonne2]],'BCP stats'!$C$6:$D$305,2,FALSE) -> 22 | G23: 69 | H23: 68 | I23: 66 | J23: 68 | K23: 68 | L23: 60 | M23: =AVERAGE(Tableau1[[#This Row],[Lepool.com]:[CBS]]) -> 66.5 | N23: =VLOOKUP(Tableau1[[#This Row],[Colonne2]],Final!$B$3:$I$302,4,FALSE) -> 82 | O23: =VLOOKUP(Tableau1[[#This Row],[Colonne2]],Final!$B$3:$I$302,7,FALSE) -> 58 | P23: =Tableau1[[#This Row],[Final]]-Tableau1[[#This Row],[Lepool.com]] -> -11 | Q23: =Tableau1[[#This Row],[Final]]-Tableau1[[#This Row],[HM]] -> -10 | R23: =Tableau1[[#This Row],[Final]]-Tableau1[[#This Row],[Pool Pro]] -> -8 | S23: =Tableau1[[#This Row],[Final]]-Tableau1[[#This Row],[ESPN]] -> -10 | T23: =Tableau1[[#This Row],[Final]]-Tableau1[[#This Row],[CBS]] -> -2 | U23: =Tableau1[[#This Row],[Final]]-Tableau1[[#This Row],[Moyenne]] -> -8.5
B24: Rasmus | C24: Ristolainen | D24: =Tableau1[[#This Row],[Prenom]]&" "&Tableau1[[#This Row],[Nom]] -> Rasmus Ristolainen | E24: =VLOOKUP(Tableau1[[#This Row],[Colonne2]],'BCP stats'!$C$6:$D$305,2,FALSE) -> 22 | G24: 45 | H24: 47 | I24: 45 | J24: 46 | K24: 41 | L24: 39 | M24: =AVERAGE(Tableau1[[#This Row],[Lepool.com]:[CBS]]) -> 43.833333 | N24: =VLOOKUP(Tableau1[[#This Row],[Colonne2]],Final!$B$3:$I$302,4,FALSE) -> 79 | O24: =VLOOKUP(Tableau1[[#This Row],[Colonne2]],Final!$B$3:$I$302,7,FALSE) -> 45 | P24: =Tableau1[[#This Row],[Final]]-Tableau1[[#This Row],[Lepool.com]] -> 0 | Q24: =Tableau1[[#This Row],[Final]]-Tableau1[[#This Row],[HM]] -> -2 | R24: =Tableau1[[#This Row],[Final]]-Tableau1[[#This Row],[Pool Pro]] -> 0 | S24: =Tableau1[[#This Row],[Final]]-Tableau1[[#This Row],[ESPN]] -> 4 | T24: =Tableau1[[#This Row],[Final]]-Tableau1[[#This Row],[CBS]] -> 6 | U24: =Tableau1[[#This Row],[Final]]-Tableau1[[#This Row],[Moyenne]] -> 1.1666667
B25: Alexander | C25: Wennberg | D25: =Tableau1[[#This Row],[Prenom]]&" "&Tableau1[[#This Row],[Nom]] -> Alexander Wennberg | E25: =VLOOKUP(Tableau1[[#This Row],[Colonne2]],'BCP stats'!$C$6:$D$305,2,FALSE) -> 22 | G25: 51 | H25: 52 | I25: 42 | J25: 52 | L25: 49 | M25: =AVERAGE(Tableau1[[#This Row],[Lepool.com]:[CBS]]) -> 49.2 | N25: =VLOOKUP(Tableau1[[#This Row],[Colonne2]],Final!$B$3:$I$302,4,FALSE) -> 80 | O25: =VLOOKUP(Tableau1[[#This Row],[Colonne2]],Final!$B$3:$I$302,7,FALSE) -> 59 | P25: =Tableau1[[#This Row],[Final]]-Tableau1[[#This Row],[Lepool.com]] -> 8 | Q25: =Tableau1[[#This Row],[Final]]-Tableau1[[#This Row],[HM]] -> 7 | R25: =Tableau1[[#This Row],[Final]]-Tableau1[[#This Row],[Pool Pro]] -> 17 | S25: =Tableau1[[#This Row],[Final]]-Tableau1[[#This Row],[ESPN]] -> 59 | T25: =Tableau1[[#This Row],[Final]]-Tableau1[[#This Row],[CBS]] -> 10 | U25: =Tableau1[[#This Row],[Final]]-Tableau1[[#This Row],[Moyenne]] -> 9.8
B26: Jonathan | C26: Huberdeau | D26: =Tableau1[[#This Row],[Prenom]]&" "&Tableau1[[#This Row],[Nom]] -> Jonathan Huberdeau | E26: =VLOOKUP(Tableau1[[#This Row],[Colonne2]],'BCP stats'!$C$6:$D$305,2,FALSE) -> 23 | G26: 67 | H26: 66 | I26: 63 | J26: 67 | K26: 60 | L26: 59 | M26: =AVERAGE(Tableau1[[#This Row],[Lepool.com]:[CBS]]) -> 63.666667 | N26: =VLOOKUP(Tableau1[[#This Row],[Colonne2]],Final!$B$3:$I$302,4,FALSE) -> 31 | O26: =VLOOKUP(Tableau1[[#This Row],[Colonne2]],Final!$B$3:$I$302,7,FALSE) -> 26 | P26: =Tableau1[[#This Row],[Final]]-Tableau1[[#This Row],[Lepool.com]] -> -41 | Q26: =Tableau1[[#This Row],[Final]]-Tableau1[[#This Row],[HM]] -> -40 | R26: =Tableau1[[#This Row],[Final]]-Tableau1[[#This Row],[Pool Pro]] -> -37 | S26: =Tableau1[[#This Row],[Final]]-Tableau1[[#This Row],[ESPN]] -> -34 | T26: =Tableau1[[#This Row],[Final]]-Tableau1[[#This Row],[CBS]] -> -33 | U26: =Tableau1[[#This Row],[Final]]-Tableau1[[#This Row],[Moyenne]] -> -37.666667
B27: Johnny | C27: Gaudreau | D27: =Tableau1[[#This Row],[Prenom]]&" "&Tableau1[[#This Row],[Nom]] -> Johnny Gaudreau | E27: =VLOOKUP(Tableau1[[#This Row],[Colonne2]],'BCP stats'!$C$6:$D$305,2,FALSE) -> 23 | G27: 80 | H27: 84 | I27: 74 | J27: 80 | K27: 84 | L27: 77 | M27: =AVERAGE(Tableau1[[#This Row],[Lepool.com]:[CBS]]) -> 79.833333 | N27: =VLOOKUP(Tableau1[[#This Row],[Colonne2]],Final!$B$3:$I$302,4,FALSE) -> 72 | O27: =VLOOKUP(Tableau1[[#This Row],[Colonne2]],Final!$B$3:$I$302,7,FALSE) -> 61 | P27: =Tableau1[[#This Row],[Final]]-Tableau1[[#This Row],[Lepool.com]] -> -19 | Q27: =Tableau1[[#This Row],[Final]]-Tableau1[[#This Row],[HM]] -> -23 | R27: =Tableau1[[#This Row],[Final]]-Tableau1[[#This Row],[Pool Pro]] -> -13 | S27: =Tableau1[[#This Row],[Final]]-Tableau1[[#This Row],[ESPN]] -> -23 | T27: =Tableau1[[#This Row],[Final]]-Tableau1[[#This Row],[CBS]] -> -16 | U27: =Tableau1[[#This Row],[Final]]-Tableau1[[#This Row],[Moyenne]] -> -18.833333
B28: Mika | C28: Zibanejad | D28: =Tableau1[[#This Row],[Prenom]]&" "&Tableau1[[#This Row],[Nom]] -> Mika Zibanejad | E28: =VLOOKUP(Tableau1[[#This Row],[Colonne2]],'BCP stats'!$C$6:$D$305,2,FALSE) -> 23 | G28: 58 | H28: 55 | I28: 55 | J28: 50 | K28: 48 | L28: 54 | M28: =AVERAGE(Tableau1[[#This Row],[Lepool.com]:[CBS]]) -> 53.333333 | N28: =VLOOKUP(Tableau1[[#This Row],[Colonne2]],Final!$B$3:$I$302,4,FALSE) -> 56 | O28: =VLOOKUP(Tableau1[[#This Row],[Colonne2]],Final!$B$3:$I$302,7,FALSE) -> 37 | P28: =Tableau1[[#This Row],[Final]]-Tableau1[[#This Row],[Lepool.com]] -> -21 | Q28: =Tableau1[[#This Row],[Final]]-Tableau1[[#This Row],[HM]] -> -18 | R28: =Tableau1[[#This Row],[Final]]-Tableau1[[#This Row],[Pool Pro]] -> -18 | S28: =Tableau1[[#This Row],[Final]]-Tableau1[[#This Row],[ESPN]] -> -11 | T28: =Tableau1[[#This Row],[Final]]-Tableau1[[#This Row],[CBS]] -> -17 | U28: =Tableau1[[#This Row],[Final]]-Tableau1[[#This Row],[Moyenne]] -> -16.333333
B29: Boone | C29: Jenner | D29: =Tableau1[[#This Row],[Prenom]]&" "&Tableau1[[#This Row],[Nom]] -> Boone Jenner | E29: =VLOOKUP(Tableau1[[#This Row],[Colonne2]],'BCP stats'!$C$6:$D$305,2,FALSE) -> 23 | G29: 53 | H29: 51 | I29: 46 | J29: 56 | K29: 47 | L29: 49 | M29: =AVERAGE(Tableau1[[#This Row],[Lepool.com]:[CBS]]) -> 50.333333 | N29: =VLOOKUP(Tableau1[[#This Row],[Colonne2]],Final!$B$3:$I$302,4,FALSE) -> 82 | O29: =VLOOKUP(Tableau1[[#This Row],[Colonne2]],Final!$B$3:$I$302,7,FALSE) -> 34 | P29: =Tableau1[[#This Row],[Final]]-Tableau1[[#This Row],[Lepool.com]] -> -19 | Q29: =Tableau1[[#This Row],[Final]]-Tableau1[[#This Row],[HM]] -> -17 | R29: =Tableau1[[#This Row],[Final]]-Tableau1[[#This Row],[Pool Pro]] -> -12 | S29: =Tableau1[[#This Row],[Final]]-Tableau1[[#This Row],[ESPN]] -> -13 | T29: =Tableau1[[#This Row],[Final]]-Tableau1[[#This Row],[CBS]] -> -15 | U29: =Tableau1[[#This Row],[Final]]-Tableau1[[#This Row],[Moyenne]] -> -16.333333
B30: Shayne | C30: Gostisbehere | D30: =Tableau1[[#This Row],[Prenom]]&" "&Tableau1[[#This Row],[Nom]] -> Shayne Gostisbehere | E30: =VLOOKUP(Tableau1[[#This Row],[Colonne2]],'BCP stats'!$C$6:$D$305,2,FALSE) -> 23 | G30: 51 | H30: 51 | I30: 44 | J30: 43 | L30: 58 | M30: =AVERAGE(Tableau1[[#This Row],[Lepool.com]:[CBS]]) -> 49.4 | N30: =VLOOKUP(Tableau1[[#This Row],[Colonne2]],Final!$B$3:$I$302,4,FALSE) -> 76 | O30: =VLOOKUP(Tableau1[[#This Row],[Colonne2]],Final!$B$3:$I$302,7,FALSE) -> 39 | P30: =Tableau1[[#This Row],[Final]]-Tableau1[[#This Row],[Lepool.com]] -> -12 | Q30: =Tableau1[[#This Row],[Final]]-Tableau1[[#This Row],[HM]] -> -12 | R30: =Tableau1[[#This Row],[Final]]-Tableau1[[#This Row],[Pool Pro]] -> -5 | S30: =Tableau1[[#This Row],[Final]]-Tableau1[[#This Row],[ESPN]] -> 39 | T30: =Tableau1[[#This Row],[Final]]-Tableau1[[#This Row],[CBS]] -> -19 | U30: =Tableau1[[#This Row],[Final]]-Tableau1[[#This Row],[Moyenne]] -> -10.4
B31: Victor | C31: Rask | D31: =Tableau1[[#This Row],[Prenom]]&" "&Tableau1[[#This Row],[Nom]] -> Victor Rask | E31: =VLOOKUP(Tableau1[[#This Row],[Colonne2]],'BCP stats'!$C$6:$D$305,2,FALSE) -> 23 | G31: 52 | H31: 51 | I31: 51 | J31: 54 | K31: 48 | L31: 51 | M31: =AVERAGE(Tableau1[[#This Row],[Lepool.com]:[CBS]]) -> 51.166667 | N31: =VLOOKUP(Tableau1[[#This Row],[Colonne2]],Final!$B$3:$I$302,4,FALSE) -> 82 | O31: =VLOOKUP(Tableau1[[#This Row],[Colonne2]],Final!$B$3:$I$302,7,FALSE) -> 45 | P31: =Tableau1[[#This Row],[Final]]-Tableau1[[#This Row],[Lepool.com]] -> -7 | Q31: =Tableau1[[#This Row],[Final]]-Tableau1[[#This Row],[HM]] -> -6 | R31: =Tableau1[[#This Row],[Final]]-Tableau1[[#This Row],[Pool Pro]] -> -6 | S31: =Tableau1[[#This Row],[Final]]-Tableau1[[#This Row],[ESPN]] -> -3 | T31: =Tableau1[[#This Row],[Final]]-Tableau1[[#This Row],[CBS]] -> -6 | U31: =Tableau1[[#This Row],[Final]]-Tableau1[[#This Row],[Moyenne]] -> -6.1666667
B32: Ryan | C32: Nugent-Hopkins | D32: =Tableau1[[#This Row],[Prenom]]&" "&Tableau1[[#This Row],[Nom]] -> Ryan Nugent-Hopkins | E32: =VLOOKUP(Tableau1[[#This Row],[Colonne2]],'BCP stats'!$C$6:$D$305,2,FALSE) -> 23 | G32: 60 | H32: 49 | I32: 54 | J32: 58 | K32: 48 | L32: 50 | M32: =AVERAGE(Tableau1[[#This Row],[Lepool.com]:[CBS]]) -> 53.166667 | N32: =VLOOKUP(Tableau1[[#This Row],[Colonne2]],Final!$B$3:$I$302,4,FALSE) -> 82 | O32: =VLOOKUP(Tableau1[[#This Row],[Colonne2]],Final!$B$3:$I$302,7,FALSE) -> 43 | P32: =Tableau1[[#This Row],[Final]]-Tableau1[[#This Row],[Lepool.com]] -> -17 | Q32: =Tableau1[[#This Row],[Final]]-Tableau1[[#This Row],[HM]] -> -6 | R32: =Tableau1[[#This Row],[Final]]-Tableau1[[#This Row],[Pool Pro]] -> -11 | S32: =Tableau1[[#This Row],[Final]]-Tableau1[[#This Row],[ESPN]] -> -5 | T32: =Tableau1[[#This Row],[Final]]-Tableau1[[#This Row],[CBS]] -> -7 | U32: =Tableau1[[#This Row],[Final]]-Tableau1[[#This Row],[Moyenne]] -> -10.166667
B33: Vincent | C33: Trocheck | D33: =Tableau1[[#This Row],[Prenom]]&" "&Tableau1[[#This Row],[Nom]] -> Vincent Trocheck | E33: =VLOOKUP(Tableau1[[#This Row],[Colonne2]],'BCP stats'!$C$6:$D$305,2,FALSE) -> 23 | G33: 57 | H33: 59 | I33: 58 | J33: 58 | K33: 43 | L33: 55 | M33: =AVERAGE(Tableau1[[#This Row],[Lepool.com]:[CBS]]) -> 55 | N33: =VLOOKUP(Tableau1[[#This Row],[Colonne2]],Final!$B$3:$I$302,4,FALSE) -> 82 | O33: =VLOOKUP(Tableau1[[#This Row],[Colonne2]],Final!$B$3:$I$302,7,FALSE) -> 54 | P33: =Tableau1[[#This Row],[Final]]-Tableau1[[#This Row],[Lepool.com]] -> -3 | Q33: =Tableau1[[#This Row],[Final]]-Tableau1[[#This Row],[HM]] -> -5 | R33: =Tableau1[[#This Row],[Final]]-Tableau1[[#This Row],[Pool Pro]] -> -4 | S33: =Tableau1[[#This Row],[Final]]-Tableau1[[#This Row],[ESPN]] -> 11 | T33: =Tableau1[[#This Row],[Final]]-Tableau1[[#This Row],[CBS]] -> -1 | U33: =Tableau1[[#This Row],[Final]]-Tableau1[[#This Row],[Moyenne]] -> -1
B34: Rickard | C34: Rakell | D34: =Tableau1[[#This Row],[Prenom]]&" "&Tableau1[[#This Row],[Nom]] -> Rickard Rakell | E34: =VLOOKUP(Tableau1[[#This Row],[Colonne2]],'BCP stats'!$C$6:$D$305,2,FALSE) -> 23 | G34: 49 | H34: 50 | I34: 47 | J34: 46 | K34: 51 | L34: 53 | M34: =AVERAGE(Tableau1[[#This Row],[Lepool.com]:[CBS]]) -> 49.333333 | N34: =VLOOKUP(Tableau1[[#This Row],[Colonne2]],Final!$B$3:$I$302,4,FALSE) -> 71 | O34: =VLOOKUP(Tableau1[[#This Row],[Colonne2]],Final!$B$3:$I$302,7,FALSE) -> 51 | P34: =Tableau1[[#This Row],[Final]]-Tableau1[[#This Row],[Lepool.com]] -> 2 | Q34: =Tableau1[[#This Row],[Final]]-Tableau1[[#This Row],[HM]] -> 1 | R34: =Tableau1[[#This Row],[Final]]-Tableau1[[#This Row],[Pool Pro]] -> 4 | S34: =Tableau1[[#This Row],[Final]]-Tableau1[[#This Row],[ESPN]] -> 0 | T34: =Tableau1[[#This Row],[Final]]-Tableau1[[#This Row],[CBS]] -> -2 | U34: =Tableau1[[#This Row],[Final]]-Tableau1[[#This Row],[Moyenne]] -> 1.6666667
B35: Dougie | C35: Hamilton | D35: =Tableau1[[#This Row],[Prenom]]&" "&Tableau1[[#This Row],[Nom]] -> Dougie Hamilton | E35: =VLOOKUP(Tableau1[[#This Row],[Colonne2]],'BCP stats'!$C$6:$D$305,2,FALSE) -> 23 | H35: 45 | I35: 45 | J35: 42 | K35: 44 | L35: 39 | M35: =AVERAGE(Tableau1[[#This Row],[Lepool.com]:[CBS]]) -> 43 | N35: =VLOOKUP(Tableau1[[#This Row],[Colonne2]],Final!$B$3:$I$302,4,FALSE) -> 81 | O35: =VLOOKUP(Tableau1[[#This Row],[Colonne2]],Final!$B$3:$I$302,7,FALSE) -> 50 | P35: =Tableau1[[#This Row],[Final]]-Tableau1[[#This Row],[Lepool.com]] -> 50 | Q35: =Tableau1[[#This Row],[Final]]-Tableau1[[#This Row],[HM]] -> 5 | R35: =Tableau1[[#This Row],[Final]]-Tableau1[[#This Row],[Pool Pro]] -> 5 | S35: =Tableau1[[#This Row],[Final]]-Tableau1[[#This Row],[ESPN]] -> 6 | T35: =Tableau1[[#This Row],[Final]]-Tableau1[[#This Row],[CBS]] -> 11 | U35: =Tableau1[[#This Row],[Final]]-Tableau1[[#This Row],[Moyenne]] -> 7
B36: Nikita | C36: Kucherov | D36: =Tableau1[[#This Row],[Prenom]]&" "&Tableau1[[#This Row],[Nom]] -> Nikita Kucherov | E36: =VLOOKUP(Tableau1[[#This Row],[Colonne2]],'BCP stats'!$C$6:$D$305,2,FALSE) -> 23 | G36: 69 | H36: 72 | I36: 70 | J36: 77 | K36: 74 | L36: 85 | M36: =AVERAGE(Tableau1[[#This Row],[Lepool.com]:[CBS]]) -> 74.5 | N36: =VLOOKUP(Tableau1[[#This Row],[Colonne2]],Final!$B$3:$I$302,4,FALSE) -> 74 | O36: =VLOOKUP(Tableau1[[#This Row],[Colonne2]],Final!$B$3:$I$302,7,FALSE) -> 85 | P36: =Tableau1[[#This Row],[Final]]-Tableau1[[#This Row],[Lepool.com]] -> 16 | Q36: =Tableau1[[#This Row],[Final]]-Tableau1[[#This Row],[HM]] -> 13 | R36: =Tableau1[[#This Row],[Final]]-Tableau1[[#This Row],[Pool Pro]] -> 15 | S36: =Tableau1[[#This Row],[Final]]-Tableau1[[#This Row],[ESPN]] -> 11 | T36: =Tableau1[[#This Row],[Final]]-Tableau1[[#This Row],[CBS]] -> 0 | U36: =Tableau1[[#This Row],[Final]]-Tableau1[[#This Row],[Moyenne]] -> 10.5
B37: Mark | C37: Scheifele | D37: =Tableau1[[#This Row],[Prenom]]&" "&Tableau1[[#This Row],[Nom]] -> Mark Scheifele | E37: =VLOOKUP(Tableau1[[#This Row],[Colonne2]],'BCP stats'!$C$6:$D$305,2,FALSE) -> 23 | G37: 72 | H37: 68 | I37: 70 | J37: 70 | K37: 61 | L37: 70 | M37: =AVERAGE(Tableau1[[#This Row],[Lepool.com]:[CBS]]) -> 68.5 | N37: =VLOOKUP(Tableau1[[#This Row],[Colonne2]],Final!$B$3:$I$302,4,FALSE) -> 79 | O37: =VLOOKUP(Tableau1[[#This Row],[Colonne2]],Final!$B$3:$I$302,7,FALSE) -> 82 | P37: =Tableau1[[#This Row],[Final]]-Tableau1[[#This Row],[Lepool.com]] -> 10 | Q37: =Tableau1[[#This Row],[Final]]-Tableau1[[#This Row],[HM]] -> 14 | R37: =Tableau1[[#This Row],[Final]]-Tableau1[[#This Row],[Pool Pro]] -> 12 | S37: =Tableau1[[#This Row],[Final]]-Tableau1[[#This Row],[ESPN]] -> 21 | T37: =Tableau1[[#This Row],[Final]]-Tableau1[[#This Row],[CBS]] -> 12 | U37: =Tableau1[[#This Row],[Final]]-Tableau1[[#This Row],[Moyenne]] -> 13.5
B38: J.T. | C38: Miller | D38: =Tableau1[[#This Row],[Prenom]]&" "&Tableau1[[#This Row],[Nom]] -> J.T. Miller | E38: =VLOOKUP(Tableau1[[#This Row],[Colonne2]],'BCP stats'!$C$6:$D$305,2,FALSE) -> 23 | G38: 49 | H38: 41 | I38: 41 | J38: 43 | K38: 45 | L38: 45 | M38: =AVERAGE(Tableau1[[#This Row],[Lepool.com]:[CBS]]) -> 44 | N38: =VLOOKUP(Tableau1[[#This Row],[Colonne2]],Final!$B$3:$I$302,4,FALSE) -> 82 | O38: =VLOOKUP(Tableau1[[#This Row],[Colonne2]],Final!$B$3:$I$302,7,FALSE) -> 56 | P38: =Tableau1[[#This Row],[Final]]-Tableau1[[#This Row],[Lepool.com]] -> 7 | Q38: =Tableau1[[#This Row],[Final]]-Tableau1[[#This Row],[HM]] -> 15 | R38: =Tableau1[[#This Row],[Final]]-Tableau1[[#This Row],[Pool Pro]] -> 15 | S38: =Tableau1[[#This Row],[Final]]-Tableau1[[#This Row],[ESPN]] -> 11 | T38: =Tableau1[[#This Row],[Final]]-Tableau1[[#This Row],[CBS]] -> 11 | U38: =Tableau1[[#This Row],[Final]]-Tableau1[[#This Row],[Moyenne]] -> 12
B39: Tyler | C39: Toffoli | D39: =Tableau1[[#This Row],[Prenom]]&" "&Tableau1[[#This Row],[Nom]] -> Tyler Toffoli | E39: =VLOOKUP(Tableau1[[#This Row],[Colonne2]],'BCP stats'!$C$6:$D$305,2,FALSE) -> 24 | G39: 61 | H39: 60 | I39: 64 | J39: 60 | K39: 64 | L39: 57 | M39: =AVERAGE(Tableau1[[#This Row],[Lepool.com]:[CBS]]) -> 61 | N39: =VLOOKUP(Tableau1[[#This Row],[Colonne2]],Final!$B$3:$I$302,4,FALSE) -> 63 | O39: =VLOOKUP(Tableau1[[#This Row],[Colonne2]],Final!$B$3:$I$302,7,FALSE) -> 34 | P39: =Tableau1[[#This Row],[Final]]-Tableau1[[#This Row],[Lepool.com]] -> -27 | Q39: =Tableau1[[#This Row],[Final]]-Tableau1[[#This Row],[HM]] -> -26 | R39: =Tableau1[[#This Row],[Final]]-Tableau1[[#This Row],[Pool Pro]] -> -30 | S39: =Tableau1[[#This Row],[Final]]-Tableau1[[#This Row],[ESPN]] -> -30 | T39: =Tableau1[[#This Row],[Final]]-Tableau1[[#This Row],[CBS]] -> -23 | U39: =Tableau1[[#This Row],[Final]]-Tableau1[[#This Row],[Moyenne]] -> -27
B40: Brendan | C40: Gallagher | D40: =Tableau1[[#This Row],[Prenom]]&" "&Tableau1[[#This Row],[Nom]] -> Brendan Gallagher | E40: =VLOOKUP(Tableau1[[#This Row],[Colonne2]],'BCP stats'!$C$6:$D$305,2,FALSE) -> 24 | G40: 55 | H40: 54 | I40: 52 | J40: 47 | K40: 44 | L40: 57 | M40: =AVERAGE(Tableau1[[#This Row],[Lepool.com]:[CBS]]) -> 51.5 | N40: =VLOOKUP(Tableau1[[#This Row],[Colonne2]],Final!$B$3:$I$302,4,FALSE) -> 64 | O40: =VLOOKUP(Tableau1[[#This Row],[Colonne2]],Final!$B$3:$I$302,7,FALSE) -> 29 | P40: =Tableau1[[#This Row],[Final]]-Tableau1[[#This Row],[Lepool.com]] -> -26 | Q40: =Tableau1[[#This Row],[Final]]-Tableau1[[#This Row],[HM]] -> -25 | R40: =Tableau1[[#This Row],[Final]]-Tableau1[[#This Row],[Pool Pro]] -> -23 | S40: =Tableau1[[#This Row],[Final]]-Tableau1[[#This Row],[ESPN]] -> -15 | T40: =Tableau1[[#This Row],[Final]]-Tableau1[[#This Row],[CBS]] -> -28 | U40: =Tableau1[[#This Row],[Final]]-Tableau1[[#This Row],[Moyenne]] -> -22.5
...

Sheet Comparatif listes
B1: Lepool | C1: HM | D1: Pool Pro | E1: ESPN | F1: CBS | G1: Moyenne
A2: 0 | B2: =COUNTIF(Tableau1[Lepool.com2],"=0") -> 6 | C2: =COUNTIF(Tableau1[HM2],"=0") -> 5 | D2: =COUNTIF(Tableau1[Pool Pro2],"=0") -> 6 | E2: =COUNTIF(Tableau1[ESPN2],"=0") -> 5 | F2: =COUNTIF(Tableau1[CBS2],"=0") -> 4 | G2: =COUNTIF(Tableau1[Moyenne2],"=0") -> 0
A3: 2 | B3: =SUMPRODUCT((Tableau1[Lepool.com2]>=-$A3)*(Tableau1[Lepool.com2]<=$A3)) -> 21 | C3: =SUMPRODUCT((Tableau1[HM2]>=-$A3)*(Tableau1[HM2]<=$A3)) -> 24 | D3: =SUMPRODUCT((Tableau1[Pool Pro2]>=-$A3)*(Tableau1[Pool Pro2]<=$A3)) -> 19 | E3: =SUMPRODUCT((Tableau1[ESPN2]>=-$A3)*(Tableau1[ESPN2]<=$A3)) -> 25 | F3: =SUMPRODUCT((Tableau1[CBS2]>=-$A3)*(Tableau1[CBS2]<=$A3)) -> 18 | G3: =SUMPRODUCT((Tableau1[Moyenne2]>=-$A3)*(Tableau1[Moyenne2]<=$A3)) -> 26
A4: 5 | B4: =SUMPRODUCT((Tableau1[Lepool.com2]>=-$A4)*(Tableau1[Lepool.com2]<=$A4)) -> 43 | C4: =SUMPRODUCT((Tableau1[HM2]>=-$A4)*(Tableau1[HM2]<=$A4)) -> 46 | D4: =SUMPRODUCT((Tableau1[Pool Pro2]>=-$A4)*(Tableau1[Pool Pro2]<=$A4)) -> 46 | E4: =SUMPRODUCT((Tableau1[ESPN2]>=-$A4)*(Tableau1[ESPN2]<=$A4)) -> 62 | F4: =SUMPRODUCT((Tableau1[CBS2]>=-$A4)*(Tableau1[CBS2]<=$A4)) -> 40 | G4: =SUMPRODUCT((Tableau1[Moyenne2]>=-$A4)*(Tableau1[Moyenne2]<=$A4)) -> 50
A5: 10 | B5: =SUMPRODUCT((Tableau1[Lepool.com2]>=-$A5)*(Tableau1[Lepool.com2]<=$A5)) -> 83 | C5: =SUMPRODUCT((Tableau1[HM2]>=-$A5)*(Tableau1[HM2]<=$A5)) -> 88 | D5: =SUMPRODUCT((Tableau1[Pool Pro2]>=-$A5)*(Tableau1[Pool Pro2]<=$A5)) -> 84 | E5: =SUMPRODUCT((Tableau1[ESPN2]>=-$A5)*(Tableau1[ESPN2]<=$A5)) -> 95 | F5: =SUMPRODUCT((Tableau1[CBS2]>=-$A5)*(Tableau1[CBS2]<=$A5)) -> 79 | G5: =SUMPRODUCT((Tableau1[Moyenne2]>=-$A5)*(Tableau1[Moyenne2]<=$A5)) -> 91
A6: 15 | B6: =SUMPRODUCT((Tableau1[Lepool.com2]>=-$A6)*(Tableau1[Lepool.com2]<=$A6)) -> 116 | C6: =SUMPRODUCT((Tableau1[HM2]>=-$A6)*(Tableau1[HM2]<=$A6)) -> 127 | D6: =SUMPRODUCT((Tableau1[Pool Pro2]>=-$A6)*(Tableau1[Pool Pro2]<=$A6)) -> 125 | E6: =SUMPRODUCT((Tableau1[ESPN2]>=-$A6)*(Tableau1[ESPN2]<=$A6)) -> 121 | F6: =SUMPRODUCT((Tableau1[CBS2]>=-$A6)*(Tableau1[CBS2]<=$A6)) -> 115 | G6: =SUMPRODUCT((Tableau1[Moyenne2]>=-$A6)*(Tableau1[Moyenne2]<=$A6)) -> 122
A7: 20 | B7: =SUMPRODUCT((Tableau1[Lepool.com2]>=-$A7)*(Tableau1[Lepool.com2]<=$A7)) -> 134 | C7: =SUMPRODUCT((Tableau1[HM2]>=-$A7)*(Tableau1[HM2]<=$A7)) -> 152 | D7: =SUMPRODUCT((Tableau1[Pool Pro2]>=-$A7)*(Tableau1[Pool Pro2]<=$A7)) -> 144 | E7: =SUMPRODUCT((Tableau1[ESPN2]>=-$A7)*(Tableau1[ESPN2]<=$A7)) -> 134 | F7: =SUMPRODUCT((Tableau1[CBS2]>=-$A7)*(Tableau1[CBS2]<=$A7)) -> 142 | G7: =SUMPRODUCT((Tableau1[Moyenne2]>=-$A7)*(Tableau1[Moyenne2]<=$A7)) -> 147
A8: 25 | B8: =SUMPRODUCT((Tableau1[Lepool.com2]>=-$A8)*(Tableau1[Lepool.com2]<=$A8)) -> 149 | C8: =SUMPRODUCT((Tableau1[HM2]>=-$A8)*(Tableau1[HM2]<=$A8)) -> 167 | D8: =SUMPRODUCT((Tableau1[Pool Pro2]>=-$A8)*(Tableau1[Pool Pro2]<=$A8)) -> 160 | E8: =SUMPRODUCT((Tableau1[ESPN2]>=-$A8)*(Tableau1[ESPN2]<=$A8)) -> 148 | F8: =SUMPRODUCT((Tableau1[CBS2]>=-$A8)*(Tableau1[CBS2]<=$A8)) -> 155 | G8: =SUMPRODUCT((Tableau1[Moyenne2]>=-$A8)*(Tableau1[Moyenne2]<=$A8)) -> 163
A9: 30 | B9: =SUMPRODUCT((Tableau1[Lepool.com2]>=-$A9)*(Tableau1[Lepool.com2]<=$A9)) -> 157 | C9: =SUMPRODUCT((Tableau1[HM2]>=-$A9)*(Tableau1[HM2]<=$A9)) -> 170 | D9: =SUMPRODUCT((Tableau1[Pool Pro2]>=-$A9)*(Tableau1[Pool Pro2]<=$A9)) -> 165 | E9: =SUMPRODUCT((Tableau1[ESPN2]>=-$A9)*(Tableau1[ESPN2]<=$A9)) -> 155 | F9: =SUMPRODUCT((Tableau1[CBS2]>=-$A9)*(Tableau1[CBS2]<=$A9)) -> 165 | G9: =SUMPRODUCT((Tableau1[Moyenne2]>=-$A9)*(Tableau1[Moyenne2]<=$A9)) -> 169
A10: 35 | B10: =SUMPRODUCT((Tableau1[Lepool.com2]>=-$A10)*(Tableau1[Lepool.com2]<=$A10)) -> 160 | C10: =SUMPRODUCT((Tableau1[HM2]>=-$A10)*(Tableau1[HM2]<=$A10)) -> 172 | D10: =SUMPRODUCT((Tableau1[Pool Pro2]>=-$A10)*(Tableau1[Pool Pro2]<=$A10)) -> 167 | E10: =SUMPRODUCT((Tableau1[ESPN2]>=-$A10)*(Tableau1[ESPN2]<=$A10)) -> 159 | F10: =SUMPRODUCT((Tableau1[CBS2]>=-$A10)*(Tableau1[CBS2]<=$A10)) -> 170 | G10: =SUMPRODUCT((Tableau1[Moyenne2]>=-$A10)*(Tableau1[Moyenne2]<=$A10)) -> 171
A11: 40 | B11: =SUMPRODUCT((Tableau1[Lepool.com2]>=-$A11)*(Tableau1[Lepool.com2]<=$A11)) -> 164 | C11: =SUMPRODUCT((Tableau1[HM2]>=-$A11)*(Tableau1[HM2]<=$A11)) -> 174 | D11: =SUMPRODUCT((Tableau1[Pool Pro2]>=-$A11)*(Tableau1[Pool Pro2]<=$A11)) -> 169 | E11: =SUMPRODUCT((Tableau1[ESPN2]>=-$A11)*(Tableau1[ESPN2]<=$A11)) -> 162 | F11: =SUMPRODUCT((Tableau1[CBS2]>=-$A11)*(Tableau1[CBS2]<=$A11)) -> 172 | G11: =SUMPRODUCT((Tableau1[Moyenne2]>=-$A11)*(Tableau1[Moyenne2]<=$A11)) -> 173
A12: 45 | B12: =SUMPRODUCT((Tableau1[Lepool.com2]>=-$A12)*(Tableau1[Lepool.com2]<=$A12)) -> 168 | C12: =SUMPRODUCT((Tableau1[HM2]>=-$A12)*(Tableau1[HM2]<=$A12)) -> 174 | D12: =SUMPRODUCT((Tableau1[Pool Pro2]>=-$A12)*(Tableau1[Pool Pro2]<=$A12)) -> 171 | E12: =SUMPRODUCT((Tableau1[ESPN2]>=-$A12)*(Tableau1[ESPN2]<=$A12)) -> 167 | F12: =SUMPRODUCT((Tableau1[CBS2]>=-$A12)*(Tableau1[CBS2]<=$A12)) -> 172 | G12: =SUMPRODUCT((Tableau1[Moyenne2]>=-$A12)*(Tableau1[Moyenne2]<=$A12)) -> 173
A13: 50 | B13: =SUMPRODUCT((Tableau1[Lepool.com2]>=-$A13)*(Tableau1[Lepool.com2]<=$A13)) -> 169 | C13: =SUMPRODUCT((Tableau1[HM2]>=-$A13)*(Tableau1[HM2]<=$A13)) -> 174 | D13: =SUMPRODUCT((Tableau1[Pool Pro2]>=-$A13)*(Tableau1[Pool Pro2]<=$A13)) -> 171 | E13: =SUMPRODUCT((Tableau1[ESPN2]>=-$A13)*(Tableau1[ESPN2]<=$A13)) -> 169 | F13: =SUMPRODUCT((Tableau1[CBS2]>=-$A13)*(Tableau1[CBS2]<=$A13)) -> 173 | G13: =SUMPRODUCT((Tableau1[Moyenne2]>=-$A13)*(Tableau1[Moyenne2]<=$A13)) -> 174

Sheet Final
A1: NHL Scoring Leaders
B2: Player | C2: Team | D2: Pos | E2: GP | F2: Goals | G2: Assists | H2: Points | I2: Points Per Game
A3: 1 | B3: Connor McDavid | C3: EDM | D3: C | E3: 82 | F3: 30 | G3: 70 | H3: 100 | I3: 1.22
A4: 2 | B4: Sidney Crosby | C4: PIT | D4: C | E4: 75 | F4: 44 | G4: 45 | H4: 89 | I4: 1.19
A5: 3 | B5: Patrick Kane | C5: CHI | D5: RW | E5: 82 | F5: 34 | G5: 55 | H5: 89 | I5: 1.09
A6: 4 | B6: Nicklas Backstrom | C6: WAS | D6: C | E6: 82 | F6: 23 | G6: 63 | H6: 86 | I6: 1.05
A7: 5 | B7: Brad Marchand | C7: BOS | D7: LW | E7: 80 | F7: 39 | G7: 46 | H7: 85 | I7: 1.06
A8: 6 | B8: Nikita Kucherov | C8: TB | D8: RW | E8: 74 | F8: 40 | G8: 45 | H8: 85 | I8: 1.15
A9: 7 | B9: Mark Scheifele | C9: WPG | D9: C | E9: 79 | F9: 32 | G9: 50 | H9: 82 | I9: 1.04
A10: 8 | B10: Leon Draisaitl | C10: EDM | D10: C | E10: 82 | F10: 29 | G10: 48 | H10: 77 | I10: 0.94
A11: 9 | B11: Brent Burns | C11: SJ | D11: D | E11: 82 | F11: 29 | G11: 47 | H11: 76 | I11: 0.93
A12: 10 | B12: Vladimir Tarasenko | C12: STL | D12: RW | E12: 82 | F12: 39 | G12: 36 | H12: 75 | I12: 0.91
A13: 11 | B13: Blake Wheeler | C13: WPG | D13: RW | E13: 82 | F13: 26 | G13: 48 | H13: 74 | I13: 0.90
A14: 12 | B14: Artemi Panarin | C14: CHI | D14: LW | E14: 82 | F14: 31 | G14: 43 | H14: 74 | I14: 0.90
... A804: 802 | B804: Ben Street | C804: DET | D804: C | E804: 6 | F804: 0 | G804: 1 | H804: 1 | I804: 0.17

Sheet BCP stats
A1: Overall | H1: Goals | M1: Assists | R1: Points | X1: Time on Ice | AB1: per 60 All Situations | AE1: per 60 Even-Strength | AH1: per 60 Power-Play | AK1: per Game | AN1: Shots | AP1: Defensive | AR1: Faceoffs
A2: Rk | C2: Name | D2: Age | E2: Pos | F2: GP | G2: G | H2: A | I2: P | J2: PIM | K2: +/- | L2: ESG | M2: PPG | N2: SHG | O2: GWG | P2: OTG | Q2: ESA | R2: PPA | S2: SHA | T2: GWA | U2: OTA | V2: ESP | W2: PPP | X2: SHP | Y2: GWP | Z2: OTP | AA2: PPP% | AB2: TOI | AC2: ES | AD2: PP | AE2: SH | AF2: G/60 | AG2: A/60 | AH2: P/60 | AI2: ESG/60 | AJ2: ESA/60 | AK2: ESP/60 | AL2: PPG/60 | AM2: PPA/60 | AN2: PPP/60 | AO2: G/GP | AP2: A/GP | AQ2: P/GP | AR2: SHOTS | AS2: SH% | AT2: HITS | AU2: BS | AV2: FOW | AW2: FOL | AX2: FO%
A6: 1 | B6: CA | C6: Connor McDavid | D6: 19 | E6: F | F6: 82 | G6: 30 | H6: 70 | I6: 100 | J6: 26 | K6: 27 | L6: 26 | M6: 3 | N6: 1 | O6: 6 | P6: 1 | Q6: 45 | R6: 24 | S6: 1 | T6: 15 | U6: 4 | V6: 71 | W6: 27 | X6: 2 | Y6: 21 | Z6: 5 | AA6: 27.0% | AB6: 0.87986111 | AC6: 0.72013889 | AD6: 0.12569444 | AE6: 0.033333333 | AF6: 1.039 | AG6: 2.425 | AH6: 3.464 | AI6: 1.100 | AJ6: 1.905 | AK6: 3.005 | AL6: 0.727 | AM6: 5.813 | AN6: 6.540 | AO6: 0.366 | AP6: 0.854 | AQ6: 1.220 | AR6: 251 | AS6: 12.0% | AT6: 34 | AU6: 29 | AV6: 348 | AW6: 458 | AX6: 43.18%
A7: 2 | B7: CA | C7: Sidney Crosby | D7: 29 | E7: F | F7: 75 | G7: 44 | H7: 45 | I7: 89 | J7: 24 | K7: 17 | L7: 30 | M7: 14 | N7: 0 | O7: 5 | P7: 1 | Q7: 34 | R7: 11 | S7: 0 | T7: 8 | U7: 2 | V7: 64 | W7: 25 | X7: 0 | Y7: 13 | Z7: 3 | AA7: 28.1% | AB7: 0.82708333 | AC7: 0.67291667 | AD7: 0.14930556 | AE7: 0.0048611111 | AF7: 1.772 | AG7: 1.812 | AH7: 3.584 | AI7: 1.486 | AJ7: 1.684 | AK7: 3.170 | AL7: 3.119 | AM7: 2.451 | AN7: 5.570 | AO7: 0.587 | AP7: 0.600 | AQ7: 1.187 | AR7: 255 | AS7: 17.3% | AT7: 80 | AU7: 27 | AV7: 842 | AW7: 906 | AX7: 48.17%
A8: 3 | B8: US | C8: Patrick Kane | D8: 28 | E8: F | F8: 82 | G8: 34 | H8: 55 | I8: 89 | J8: 32 | K8: 11 | L8: 27 | M8: 7 | N8: 0 | O8: 5 | P8: 1 | Q8: 39 | R8: 16 | S8: 0 | T8: 14 | U8: 4 | V8: 66 | W8: 23 | X8: 0 | Y8: 19 | Z8: 5 | AA8: 25.8% | AB8: 0.89097222 | AC8: 0.74652778 | AD8: 0.14166667 | AE8: 0.0027777778 | AF8: 1.163 | AG8: 1.881 | AH8: 3.043 | AI8: 1.103 | AJ8: 1.593 | AK8: 2.695 | AL8: 1.505 | AM8: 3.440 | AN8: 4.946 | AO8: 0.415 | AP8: 0.671 | AQ8: 1.085 | AR8: 292 | AS8: 11.6% | AT8: 28 | AU8: 15 | AV8: 7 | AW8: 44 | AX8: 13.73%
A9: 4 | B9: SE | C9: Nicklas Bäckström | D9: 29 | E9: F | F9: 82 | G9: 23 | H9: 63 | I9: 86 | J9: 38 | K9: 17 | L9: 15 | M9: 8 | N9: 0 | O9: 5 | P9: 2 | Q9: 36 | R9: 27 | S9: 0 | T9: 12 | U9: 1 | V9: 51 | W9: 35 | X9: 0 | Y9: 17 | Z9: 3 | AA9: 40.7% | AB9: 0.75972222 | AC9: 0.60347222 | AD9: 0.12638889 | AE9: 0.028472222 | AF9: 0.923 | AG9: 2.528 | AH9: 3.451 | AI9: 0.757 | AJ9: 1.817 | AK9: 2.574 | AL9: 1.923 | AM9: 6.491 | AN9: 8.415 | AO9: 0.280 | AP9: 0.768 | AQ9: 1.049 | AR9: 162 | AS9: 14.2% | AT9: 45 | AU9: 33 | AV9: 685 | AW9: 648 | AX9: 51.39%
A10: 5 | B10: RU | C10: Nikita Kucherov | D10: 23 | E10: F | F10: 74 | G10: 40 | H10: 45 | I10: 85 | J10: 38 | K10: 13 | L10: 23 | M10: 17 | N10: 0 | O10: 7 | P10: 1 | Q10: 30 | R10: 15 | S10: 0 | T10: 9 | U10: 1 | V10: 53 | W10: 32 | X10: 0 | Y10: 16 | Z10: 2 | AA10: 37.6% | AB10: 0.80902778 | AC10: 0.66805556 | AD10: 0.13958333 | AE10: 0.00069444444 | AF10: 1.670 | AG10: 1.879 | AH10: 3.549 | AI10: 1.163 | AJ10: 1.517 | AK10: 2.679 | AL10: 4.104 | AM10: 3.621 | AN10: 7.726 | AO10: 0.541 | AP10: 0.608 | AQ10: 1.149 | AR10: 246 | AS10: 16.3% | AT10: 30 | AU10: 20 | AV10: 0 | AW10: 0 | AX10: 0.00%
A11: 6 | B11: CA | C11: Brad Marchand | D11: 28 | E11: F | F11: 80 | G11: 39 | H11: 46 | I11: 85 | J11: 81 | K11: 18 | L11: 27 | M11: 9 | N11: 3 | O11: 8 | P11: 1 | Q11: 29 | R11: 15 | S11: 2 | T11: 8 | U11: 0 | V11: 56 | W11: 24 | X11: 5 | Y11: 16 | Z11: 1 | AA11: 28.2% | AB11: 0.80972222 | AC11: 0.61527778 | AD11: 0.11180556 | AE11: 0.077777778 | AF11: 1.505 | AG11: 1.775 | AH11: 3.280 | AI11: 1.370 | AJ11: 1.471 | AK11: 2.841 | AL11: 2.503 | AM11: 4.172 | AN11: 6.675 | AO11: 0.488 | AP11: 0.575 | AQ11: 1.063 | AR11: 226 | AS11: 17.3% | AT11: 51 | AU11: 35 | AV11: 13 | AW11: 23 | AX11: 36.11%
A12: 7 | B12: CA | C12: Mark Scheifele | D12: 23 | E12: F | F12: 79 | G12: 32 | H12: 50 | I12: 82 | J12: 38 | K12: 18 | L12: 25 | M12: 7 | N12: 0 | O12: 5 | P12: 2 | Q12: 40 | R12: 8 | S12: 2 | T12: 7 | U12: 0 | V12: 65 | W12: 15 | X12: 2 | Y12: 12 | Z12: 2 | AA12: 18.3% | AB12: 0.85625 | AC12: 0.69791667 | AD12: 0.12916667 | AE12: 0.028472222 | AF12: 1.182 | AG12: 1.847 | AH12: 3.028 | AI12: 1.133 | AJ12: 1.812 | AK12: 2.945 | AL12: 1.712 | AM12: 1.957 | AN12: 3.668 | AO12: 0.405 | AP12: 0.633 | AQ12: 1.038 | AR12: 160 | AS12: 20.0% | AT12: 49 | AU12: 34 | AV12: 635 | AW12: 826 | AX12: 43.46%
A13: 8 | B13: DE | C13: Leon Draisaitl | D13: 21 | E13: F | F13: 82 | G13: 29 | H13: 48 | I13: 77 | J13: 20 | K13: 7 | L13: 19 | M13: 10 | N13: 0 | O13: 5 | P13: 3 | Q13: 31 | R13: 17 | S13: 0 | T13: 11 | U13: 1 | V13: 50 | W13: 27 | X13: 0 | Y13: 16 | Z13: 4 | AA13: 35.1% | AB13: 0.78611111 | AC13: 0.64722222 | AD13: 0.12013889 | AE13: 0.018055556 | AF13: 1.124 | AG13: 1.861 | AH13: 2.985 | AI13: 0.894 | AJ13: 1.459 | AK13: 2.354 | AL13: 2.528 | AM13: 4.298 | AN13: 6.826 | AO13: 0.354 | AP13: 0.585 | AQ13: 0.939 | AR13: 172 | AS13: 16.9% | AT13: 41 | AU13: 36 | AV13: 476 | AW13: 496 | AX13: 48.97%
A14: 9 | B14: CA | C14: Brent Burns | D14: 31 | E14: D | F14: 82 | G14: 29 | H14: 47 | I14: 76 | J14: 40 | K14: 19 | L14: 21 | M14: 8 | N14: 0 | O14: 6 | P14: 3 | Q14: 29 | R14: 17 | S14: 1 | T14: 11 | U14: 1 | V14: 50 | W14: 25 | X14: 1 | Y14: 17 | Z14: 4 | AA14: 32.9% | AB14: 1.0354167 | AC14: 0.80833333 | AD14: 0.14861111 | AE14: 0.070833333 | AF14: 0.853 | AG14: 1.383 | AH14: 2.237 | AI14: 0.792 | AJ14: 1.094 | AK14: 1.885 | AL14: 1.639 | AM14: 3.483 | AN14: 5.123 | AO14: 0.354 | AP14: 0.573 | AQ14: 0.927 | AR14: 320 | AS14: 9.1% | AT14: 69 | AU14: 142 | AV14: 0 | AW14: 0 | AX14: 0.00%
A15: 10 | B15: RU | C15: Vladimir Tarasenko | D15: 25 | E15: F | F15: 82 | G15: 39 | H15: 36 | I15: 75 | J15: 12 | K15: -1 | L15: 30 | M15: 9 | N15: 0 | O15: 8 | P15: 3 | Q15: 23 | R15: 13 | S15: 0 | T15: 7 | U15: 0 | V15: 53 | W15: 22 | X15: 0 | Y15: 15 | Z15: 3 | AA15: 29.3% | AB15: 0.76944444 | AC15: 0.6375 | AD15: 0.12430556 | AE15: 0.0069444444 | AF15: 1.545 | AG15: 1.426 | AH15: 2.971 | AI15: 1.434 | AJ15: 1.100 | AK15: 2.534 | AL15: 2.207 | AM15: 3.187 | AN15: 5.394 | AO15: 0.476 | AP15: 0.439 | AQ15: 0.915 | AR15: 286 | AS15: 13.6% | AT15: 50 | AU15: 31 | AV15: 5 | AW15: 5 | AX15: 50.00%
A16: 11 | B16: RU | C16: Artemi Panarin | D16: 25 | E16: F | F16: 82 | G16: 31 | H16: 43 | I16: 74 | J16: 21 | K16: 18 | L16: 22 | M16: 9 | N16: 0 | O16: 5 | P16: 1 | Q16: 35 | R16: 8 | S16: 0 | T16: 10 | U16: 3 | V16: 57 | W16: 17 | X16: 0 | Y16: 15 | Z16: 4 | AA16: 23.0% | AB16: 0.81111111 | AC16: 0.67847222 | AD16: 0.13055556 | AE16: 0.00069444444 | AF16: 1.165 | AG16: 1.616 | AH16: 2.781 | AI16: 0.988 | AJ16: 1.571 | AK16: 2.559 | AL16: 2.095 | AM16: 1.862 | AN16: 3.958 | AO16: 0.378 | AP16: 0.524 | AQ16: 0.902 | AR16: 211 | AS16: 14.7% | AT16: 23 | AU16: 14 | AV16: 2 | AW16: 8 | AX16: 20.00%
A17: 12 | B17: US | C17: Blake Wheeler | D17: 30 | E17: F | F17: 82 | G17: 26 | H17: 48 | I17: 74 | J17: 47 | K17: 6 | L17: 19 | M17: 5 | N17: 2 | O17: 4 | P17: 0 | Q17: 31 | R17: 16 | S17: 1 | T17: 6 | U17: 1 | V17: 50 | W17: 21 | X17: 3 | Y17: 10 | Z17: 1 | AA17: 28.4% | AB17: 0.83888889 | AC17: 0.65833333 | AD17: 0.12291667 | AE17: 0.057638889 | AF17: 0.945 | AG17: 1.744 | AH17: 2.688 | AI17: 0.880 | AJ17: 1.435 | AK17: 2.315 | AL17: 1.235 | AM17: 3.953 | AN17: 5.188 | AO17: 0.317 | AP17: 0.585 | AQ17: 0.902 | AR17: 259 | AS17: 10.0% | AT17: 100 | AU17: 51 | AV17: 43 | AW17: 51 | AX17: 45.74%
... A55: 50 | B55: CA | C55: Jonathan Toews | D55: 28 | E55: F | F55: 72 | G55: 21 | H55: 37 | I55: 58 | J55: 35 | K55: 7 | L55: 15 | M55: 6 | N55: 0 | O55: 5 | P55: 1 | Q55: 26 | R55: 11 | S55: 0 | T55: 7 | U55: 1 | V55: 41 | W55: 17 | X55: 0 | Y55: 12 | Z55: 2 | AA55: 29.3% | AB55: 0.83958333 | AC55: 0.67361111 | AD55: 0.11180556 | AE55: 0.054166667 | AF55: 0.868 | AG55: 1.530 | AH55: 2.398 | AI55: 0.773 | AJ55: 1.340 | AK55: 2.113 | AL55: 1.863 | AM55: 3.415 | AN55: 5.278 | AO55: 0.292 | AP55: 0.514 | AQ55: 0.806 | AR55: 199 | AS55: 10.6% | AT55: 43 | AU55: 32 | AV55: 852 | AW55: 701 | AX55: 54.86%
A56: 51 | C56: Mikko Koivu | D56: 33 | E56: F | F56: 80 | G56: 18 | H56: 40 | I56: 58 | J56: 34 | K56: 27 | L56: 16 | M56: 2 | N56: 0 | O56: 4 | P56: 1 | Q56: 20 | R56: 18 | S56: 2 | T56: 4 | U56: 1 | V56: 36 | W56: 20 | X56: 2 | Y56: 8 | Z56: 2 | AA56: 34.5% | AB56: 0.79583333 | AC56: 0.62638889 | AD56: 0.093055556 | AE56: 0.075694444 | AF56: 0.707 | AG56: 1.570 | AH56: 2.277 | AI56: 0.798 | AJ56: 0.997 | AK56: 1.795 | AL56: 0.670 | AM56: 6.031 | AN56: 6.701 | AO56: 0.225 | AP56: 0.500 | AQ56: 0.725 | AR56: 139 | AS56: 13.0% | AT56: 32 | AU56: 65 | AV56: 938 | AW56: 761 | AX56: 55.21%
A57: 52 | B57: CA | C57: Claude Giroux | D57: 28 | E57: F | F57: 82 | G57: 14 | H57: 44 | I57: 58 | J57: 38 | K57: -15 | L57: 9 | M57: 5 | N57: 0 | O57: 3 | P57: 2 | Q57: 17 | R57: 26 | S57: 1 | T57: 6 | U57: 2 | V57: 26 | W57: 31 | X57: 1 | Y57: 9 | Z57: 4 | AA57: 53.4% | AB57: 0.79722222 | AC57: 0.62847222 | AD57: 0.15555556 | AE57: 0.011111111 | AF57: 0.535 | AG57: 1.682 | AH57: 2.218 | AI57: 0.436 | AJ57: 0.824 | AK57: 1.260 | AL57: 0.977 | AM57: 5.082 | AN57: 6.059 | AO57: 0.171 | AP57: 0.537 | AQ57: 0.707 | AR57: 199 | AS57: 7.0% | AT57: 68 | AU57: 28 | AV57: 977 | AW57: 771 | AX57: 55.89%
A58: 53 | B58: CH | C58: Nino Niederreiter | D58: 24 | E58: F | F58: 82 | G58: 25 | H58: 32 | I58: 57 | J58: 53 | K58: 17 | L58: 17 | M58: 8 | N58: 0 | O58: 3 | P58: 0 | Q58: 26 | R58: 6 | S58: 0 | T58: 8 | U58: 0 | V58: 43 | W58: 14 | X58: 0 | Y58: 11 | Z58: 0 | AA58: 24.6% | AB58: 0.62777778 | AC58: 0.54375 | AD58: 0.083333333 | AE58: 0 | AF58: 1.213 | AG58: 1.553 | AH58: 2.766 | AI58: 0.952 | AJ58: 1.456 | AK58: 2.409 | AL58: 2.908 | AM58: 2.181 | AN58: 5.089 | AO58: 0.305 | AP58: 0.390 | AQ58: 0.695 | AR58: 186 | AS58: 13.4% | AT58: 120 | AU58: 20 | AV58: 0 | AW58: 1 | AX58: 0.00%
A59: 54 | B59: US | C59: Jack Eichel | D59: 20 | E59: F | F59: 61 | G59: 24 | H59: 33 | I59: 57 | J59: 22 | K59: -13 | L59: 14 | M59: 10 | N59: 0 | O59: 4 | P59: 1 | Q59: 19 | R59: 14 | S59: 0 | T59: 5 | U59: 3 | V59: 33 | W59: 24 | X59: 0 | Y59: 9 | Z59: 4 | AA59: 42.1% | AB59: 0.82986111 | AC59: 0.69513889 | AD59: 0.12361111 | AE59: 0.0097222222 | AF59: 1.185 | AG59: 1.629 | AH59: 2.815 | AI59: 0.825 | AJ59: 1.119 | AK59: 1.944 | AL59: 3.298 | AM59: 4.617 | AN59: 7.914 | AO59: 0.393 | AP59: 0.541 | AQ59: 0.934 | AR59: 249 | AS59: 9.6% | AT59: 26 | AU59: 35 | AV59: 310 | AW59: 486 | AX59: 38.94%
A60: 55 | B60: US | C60: T.J. Oshie | D60: 30 | E60: F | F60: 68 | G60: 33 | H60: 23 | I60: 56 | J60: 36 | K60: 28 | L60: 25 | M60: 7 | N60: 1 | O60: 4 | P60: 1 | Q60: 15 | R60: 6 | S60: 2 | T60: 5 | U60: 0 | V60: 40 | W60: 13 | X60: 3 | Y60: 9 | Z60: 1 | AA60: 23.2% | AB60: 0.74305556 | AC60: 0.58125 | AD60: 0.12083333 | AE60: 0.040972222 | AF60: 1.631 | AG60: 1.137 | AH60: 2.768 | AI60: 1.580 | AJ60: 0.948 | AK60: 2.529 | AL60: 2.129 | AM60: 1.825 | AN60: 3.954 | AO60: 0.485 | AP60: 0.338 | AQ60: 0.824 | AR60: 143 | AS60: 23.1% | AT60: 95 | AU60: 50 | AV60: 87 | AW60: 93 | AX60: 48.33%
A61: 56 | B61: US | C61: J.T. Miller | D61: 23 | E61: F | F61: 82 | G61: 22 | H61: 34 | I61: 56 | J61: 21 | K61: 17 | L61: 17 | M61: 2 | N61: 3 | O61: 6 | P61: 1 | Q61: 28 | R61: 5 | S61: 1 | T61: 7 | U61: 1 | V61: 45 | W61: 7 | X61: 4 | Y61: 13 | Z61: 2 | AA61: 12.5% | AB61: 0.68194444 | AC61: 0.56875 | AD61: 0.060416667 | AE61: 0.052083333 | AF61: 0.983 | AG61: 1.520 | AH61: 2.503 | AI61: 0.911 | AJ61: 1.500 | AK61: 2.411 | AL61: 1.008 | AM61: 2.520 | AN61: 3.528 | AO61: 0.268 | AP61: 0.415 | AQ61: 0.683 | AR61: 132 | AS61: 16.7% | AT61: 101 | AU61: 56 | AV61: 156 | AW61: 200 | AX61: 43.82%
A62: 57 | B62: US | C62: Charlie Coyle | D62: 24 | E62: F | F62: 82 | G62: 18 | H62: 38 | I62: 56 | J62: 36 | K62: 13 | L62: 14 | M62: 4 | N62: 0 | O62: 5 | P62: 0 | Q62: 33 | R62: 5 | S62: 0 | T62: 10 | U62: 2 | V62: 47 | W62: 9 | X62: 0 | Y62: 15 | Z62: 2 | AA62: 16.1% | AB62: 0.69583333 | AC62: 0.59236111 | AD62: 0.088888889 | AE62: 0.014583333 | AF62: 0.788 | AG62: 1.664 | AH62: 2.452 | AI62: 0.721 | AJ62: 1.698 | AK62: 2.419 | AL62: 1.371 | AM62: 1.714 | AN62: 3.085 | AO62: 0.220 | AP62: 0.463 | AQ62: 0.683 | AR62: 159 | AS62: 11.3% | AT62: 101 | AU62: 63 | AV62: 114 | AW62: 134 | AX62: 45.97%
A63: 58 | B63: CA | C63: Joshua Bailey | D63: 27 | E63: F | F63: 82 | G63: 13 | H63: 43 | I63: 56 | J63: 12 | K63: 5 | L63: 10 | M63: 3 | N63: 0 | O63: 1 | P63: 1 | Q63: 34 | R63: 9 | S63: 0 | T63: 4 | U63: 2 | V63: 44 | W63: 12 | X63: 0 | Y63: 5 | Z63: 3 | AA63: 21.4% | AB63: 0.76527778 | AC63: 0.62777778 | AD63: 0.11805556 | AE63: 0.018055556 | AF63: 0.518 | AG63: 1.713 | AH63: 2.230 | AI63: 0.486 | AJ63: 1.651 | AK63: 2.136 | AL63: 0.774 | AM63: 2.322 | AN63: 3.096 | AO63: 0.159 | AP63: 0.524 | AQ63: 0.683 | AR63: 173 | AS63: 7.5% | AT63: 37 | AU63: 53 | AV63: 8 | AW63: 7 | AX63: 53.33%
A64: 59 | B64: US | C64: Kevin Shattenkirk | D64: 27 | E64: D | F64: 80 | G64: 13 | H64: 43 | I64: 56 | J64: 47 | K64: -7 | L64: 5 | M64: 8 | N64: 0 | O64: 2 | P64: 0 | Q64: 24 | R64: 19 | S64: 0 | T64: 15 | U64: 4 | V64: 29 | W64: 27 | X64: 0 | Y64: 17 | Z64: 4 | AA64: 48.2% | AB64: 0.82986111 | AC64: 0.68402778 | AD64: 0.13263889 | AE64: 0.0125 | AF64: 0.489 | AG64: 1.618 | AH64: 2.108 | AI64: 0.228 | AJ64: 1.096 | AK64: 1.324 | AL64: 1.880 | AM64: 4.465 | AN64: 6.345 | AO64: 0.163 | AP64: 0.538 | AQ64: 0.700 | AR64: 161 | AS64: 8.1% | AT64: 88 | AU64: 95 | AV64: 0 | AW64: 0 | AX64: 0.00%
A65: 60 | B65: CA | C65: Kyle Turris | D65: 27 | E65: F | F65: 78 | G65: 27 | H65: 28 | I65: 55 | J65: 47 | K65: -3 | L65: 21 | M65: 6 | N65: 0 | O65: 6 | P65: 2 | Q65: 17 | R65: 11 | S65: 0 | T65: 6 | U65: 0 | V65: 38 | W65: 17 | X65: 0 | Y65: 12 | Z65: 2 | AA65: 30.9% | AB65: 0.8125 | AC65: 0.66111111 | AD65: 0.12152778 | AE65: 0.029861111 | AF65: 1.065 | AG65: 1.104 | AH65: 2.169 | AI65: 1.018 | AJ65: 0.824 | AK65: 1.842 | AL65: 1.581 | AM65: 2.899 | AN65: 4.481 | AO65: 0.346 | AP65: 0.359 | AQ65: 0.705 | AR65: 185 | AS65: 14.6% | AT65: 21 | AU65: 61 | AV65: 650 | AW65: 575 | AX65: 53.06%
A66: 61 | B66: CA | C66: Brayden Schenn | D66: 25 | E66: F | F66: 79 | G66: 25 | H66: 30 | I66: 55 | J66: 38 | K66: -13 | L66: 8 | M66: 17 | N66: 0 | O66: 7 | P66: 2 | Q66: 19 | R66: 11 | S66: 0 | T66: 3 | U66: 0 | V66: 27 | W66: 28 | X66: 0 | Y66: 10 | Z66: 2 | AA66: 50.9% | AB66: 0.74166667 | AC66: 0.58472222 | AD66: 0.15555556 | AE66: 0.00069444444 | AF66: 1.066 | AG66: 1.279 | AH66: 2.345 | AI66: 0.433 | AJ66: 1.028 | AK66: 1.460 | AL66: 3.443 | AM66: 2.228 | AN66: 5.672 | AO66: 0.316 | AP66: 0.380 | AQ66: 0.696 | AR66: 178 | AS66: 14.0% | AT66: 189 | AU66: 42 | AV66: 232 | AW66: 262 | AX66: 46.96%
A67: 62 | B67: CZ | C67: Radim Vrbata | D67: 35 | E67: F | F67: 81 | G67: 20 | H67: 35 | I67: 55 | J67: 16 | K67: -18 | L67: 16 | M67: 4 | N67: 0 | O67: 4 | P67: 0 | Q67: 24 | R67: 11 | S67: 0 | T67: 5 | U67: 2 | V67: 40 | W67: 15 | X67: 0 | Y67: 9 | Z67: 2 | AA67: 27.3% | AB67: 0.70347222 | AC67: 0.58055556 | AD67: 0.11180556 | AE67: 0.010416667 | AF67: 0.877 | AG67: 1.535 | AH67: 2.412 | AI67: 0.850 | AJ67: 1.275 | AK67: 2.126 | AL67: 1.098 | AM67: 3.018 | AN67: 4.116 | AO67: 0.247 | AP67: 0.432 | AQ67: 0.679 | AR67: 233 | AS67: 8.6% | AT67: 48 | AU67: 31 | AV67: 17 | AW67: 30 | AX67: 36.17%
A68: 63 | B68: CA | C68: Ryan O'Reilly | D68: 25 | E68: F | F68: 72 | G68: 20 | H68: 35 | I68: 55 | J68: 10 | K68: -1 | L68: 11 | M68: 8 | N68: 1 | O68: 3 | P68: 0 | Q68: 18 | R68: 16 | S68: 1 | T68: 8 | U68: 3 | V68: 29 | W68: 24 | X68: 2 | Y68: 11 | Z68: 3 | AA68: 43.6% | AB68: 0.89375 | AC68: 0.67569444 | AD68: 0.12013889 | AE68: 0.096527778 | AF68: 0.777 | AG68: 1.359 | AH68: 2.136 | AI68: 0.565 | AJ68: 0.925 | AK68: 1.490 | AL68: 2.302 | AM68: 4.605 | AN68: 6.907 | AO68: 0.278 | AP68: 0.486 | AQ68: 0.764 | AR68: 189 | AS68: 10.6% | AT68: 21 | AU68: 45 | AV68: 1039 | AW68: 752 | AX68: 58.01%
... A105: 100 | B105: SE | C105: Henrik Sedin | D105: 36 | E105: F | F105: 82 | G105: 15 | H105: 35 | I105: 50 | J105: 28 | K105: -27 | L105: 14 | M105: 1 | N105: 0 | O105: 4 | P105: 2 | Q105: 21 | R105: 14 | S105: 0 | T105: 5 | U105: 1 | V105: 35 | W105: 15 | X105: 0 | Y105: 9 | Z105: 3 | AA105: 30.0% | AB105: 0.79305556 | AC105: 0.66180556 | AD105: 0.12430556 | AE105: 0.00625 | AF105: 0.576 | AG105: 1.345 | AH105: 1.921 | AI105: 0.644 | AJ105: 0.967 | AK105: 1.611 | AL105: 0.245 | AM105: 3.429 | AN105: 3.674 | AO105: 0.183 | AP105: 0.427 | AQ105: 0.610 | AR105: 99 | AS105: 15.2% | AT105: 15 | AU105: 11 | AV105: 611 | AW105: 635 | AX105: 49.04%
